Workbook

Sheet MAIN PAGE
A1: ASSUMPTIONS & INPUTS | C1: UNITS | D1: conversions | F1: CALCULATIONS | H1: UNITS | M1: KEY
A2: density of air (at 20 C 1 atm) | B2: 1.2041 | C2: kg/m^3 | F2: Aspect Ratio: | G2: =(B16^2)/G6 -> 5.3333333 | H2: NA | I2: check: | J2: =B16^2/G6 -> 5.3333333 | M2: variable for all designs
A3: density of foam (EVA) | B3: 85 | C3: kg/m^3 | F3: Cross section @ AOA 0: | G3: =B18*B16 -> 1.6e-05 | H3: m^2 | M3: important results
A4: density of print (PLA) | B4: =D4*1000 -> 1240 | C4: kg/m^3 | D4: 1.24 | E4: g/cm^3 | F4: **Cross section @ AOA 11: | G4: =B16*SIN(RADIANS(B29))+G3 -> 0.01528072 | M4: design type
A5: velocity (v) | B5: 5 | C5: m/s | F5: Cross section variable AOA | G5: =B16*SIN(RADIANS(B30))+0.003 -> 0.016891854 | M5: inputs
A6: coefficient drag flat plate (Cd) | B6: 0.005 | C6: NA | F6: Top down area: | G6: =(1/2)*B16*B17 -> 0.0012 | H6: m^2
A7: coefficient drag airfoil (Cd) | B7: 0.045 | C7: NA | F7: Volume: | G7: =G6*B18 -> 2.4e-07 | H7: m^3
A8: coefficient lift plate (Cl) | B8: 0.7 | C8: NA | F8: Cross section fin: | G8: =B23*B18 -> 4e-06 | H8: m^3
A9: coefficient lift airfoil (Cl) | B9: 2 | C9: NA
A11: flapping:
A12: frequency (f) | B12: 10 | C12: Hz
A13: amplitude (A) | B13: 0.04 | C13: m
A15: dimensions: | F15: TAIL FORCES
A16: span (s) | B16: 0.08 | C16: m | D16: =B16*39.37 -> 3.1496 | E16: in | F16: Stationary tail (flat plate)
A17: chord length (c) | B17: 0.03 | C17: m | D17: =B17*39.37 -> 1.1811 | E17: in | F17: Total Drag: | G17: =(1/2)*B2*B5^2*B6*G5 -> 0.0012712176 | H17: N
A18: thickness (t) | B18: 0.0002 | C18: m | D18: =B18*39.37 -> 0.007874 | E18: in | F18: negative -z (down) | G18: =G17*SIN(RADIANS(B30)) -> 0.00022074462 | H18: N | O18: MOMENTS
A19: additional fuselage??? | B19: 0.05 | C19: m | D19: =B19*39.37 -> 1.9685 | E19: in
A20: body fuselage(l) | B20: =4*B17 -> 0.12 | C20: m | D20: =B20*39.37 -> 4.7244 | E20: in | F20: negative x (back) | G20: =G17*COS(RADIANS(B30)) -> 0.001251905 | H20: N
A21: dist tail to COL | B21: =(1/2)*B20 -> 0.06 | C21: m
A22: dihedral angle | B22: 10 | C22: deg
A23: fin height | B23: 0.02 | C23: m | F23: Total Lift: | G23: =(1/2)*B8*B2*B5^2*G6 -> 0.01264305 | H23: N
A24: fin length | B24: 0.015 | C24: m | F24: positive -z (up) | G24: =G23*SIN(RADIANS(90-B30)) -> 0.012450974 | H24: N
A25: center gravity (g) | B25: =3/4*B17 -> 0.0225 | C25: m | F25: negative x (back) | G25: =G23*COS(RADIANS(90-B30)) -> 0.0021954426 | H25: N
A26: dist COL from COG (x) | B26: 0.004 | C26: m
A28: angle of attack: | B28: 0 | C28: deg | E28: * includes 1g motor, plate, fin | F28: Total Weight: | G28: =(G7*B3)+D34+B52 -> 0.00046295 | H28: kg | I28: =G28*1000 -> 0.46295 | J28: g
A29: AOA tail (alpha) | B29: 11 | C29: deg | F29: Force gravity | G29: =G28*9.81 -> 0.0045415395 | H29: N
A30: variable | B30: 10 | C30: deg | O30: Time tail needs to move theta for forces to counter: | T30: New Simplifications
A31: AOA body (beta) | F31: Net Force in x | G31: =-G25-G20 -> -0.0034473475 | H31: N | O31: Force wing (Fwing) | P31: ='Wing Flap (rigid body)'!G12*2 -> 0.053822243 | Q31: N | T31: X2 is estimated as 1/4 of the entire body length
F32: Net Force in -z | G32: =G24-G18-G29 -> 0.0076886895 | H32: N | O32: dist Fwing to COM (X2) | P32: =(B20*1/4) -> 0.03 | Q32: m | R32: =P32*39.37 -> 1.1811 | S32: in | T32: X1 estimated as 1/3 body plus distance to COG
A33: components: | O33: dist Ftail to COM (X1) | P33: =((1/3)*B20)+B25+B19 -> 0.1125 | Q33: m | R33: =P33*39.37 -> 4.429125 | S33: in | T33: time is est by using nonlinear motion eqn and delta theta=2x the angle of attack (with max torque so abt 10 deg)
A34: motor | B34: 0.44 | C34: g | D34: =B34/1000 -> 0.00044 | E34: kg | F34: TORQUES (about base of tail) | I34: Torque abt center of body | O34: Ftail theoretical (needed) | P34: =(P31*P32)/P33 -> 0.014352598 | Q34: N
A35: SIMPLIFICATIONS | F35: Lift (clockwise) | G35: =G23*1/4*((B17)+B26) -> 0.00010746592 | H35: Nm | I35: Lift | J35: =G23*((1/4)*B17+(1/2)*B20+B26) -> 0.00090397807 | K35: Nm | L35: cw (-) | O35: mass tail | P35: =G28 -> 0.00046295 | Q35: kg
A36: **added cross section at 0 to other AOA to prevent treating infinitely flat | F36: Gravity (counterclockwise) | G36: =G29*B25*COS(RADIANS(B30)) -> 0.00010063222 | H36: Nm | I36: Gravity | J36: =G29*((1/4)*B17*COS(RADIANS(B29))+((1/2)*B20*COS(RADIANS(B31)))) -> 0.00030592811 | K36: Nm | L36: ccw | N36: ** | O36: acc tail | P36: =P34/P35 -> 31.00248 | Q36: m/s^2
A37: drag acts at the center of plate at end of tail (bc max torque) | F37: Drag | G37: 0 | H37: Nm | I37: Drag | J37: =G18*((1/2)*B20+COS(RADIANS(B30)*B17)) -> 0.00023398627 | K37: Nm | L37: ccw | O37: angular acc @ tip of tail | P37: =P36/B17 -> 1033.416 | Q37: rad/s^2
A38: lift&gravity act at 1/4 chord (!!Offset to eventually adjust) | J38: =(G20*(SIN(RADIANS(B30)*B17))) -> 6.554929e-06 | L38: cw(-) | O38: deg -> rad for AOA max | P38: =B30*(PI()/180) -> 0.17453293 | Q38: rad
A39: for now approx for fuselage length is 4-6x chord of wing | F39: Net Torque | G39: =G36-G35 -> -6.8337005e-06 | H39: Nm | I39: Net | J39: =J36-J35+J37-J38 -> -0.00037061862 | L39: (want this to be positive for ccw) | O39: time for 1 flap | P39: =SQRT((2*P38*2*B17)/P37) -> 0.0045018572 | Q39: s
A40: Cl/Cd airfoil basic for flat bottom (S7055) | F40: Wing Flap need to resist | G40: ='Wing Flap (rigid body)'!G12 -> 0.026911121 | H40: Nm | P40: hm maybe see if we could make solonoid powerful enough I can't find mini actuator specs
A41: Coeff plate estimated based on Fig 4.36
I43: DESIGN CONSIDERATIONS
A45: Tailfin | B45: **yaw stability | D45: Whole Flat Tail Movement | H45: Elevator | J45: Dihedral | K45: **lateral stability | N45: Airfoil Frame
...

Sheet Variable AOA Flat plate
A1: AOA (deg) | B1: Cross section | C1: Cd | D1: Drag | E1: Dz (down) | F1: Dx (back) | G1: Cl | H1: Lift | I1: Lz (up) | J1: Lx (back) | K1: Weight (down) | M1: NET X (back) | N1: NET Z (up) | P1: Base of Tail Torques: | Q1: Lift | R1: Gravity | S1: Net | U1: Fuselage Torques: | V1: Lift | W1: Gravity | X1: Net
A3: 0 | B3: ='MAIN PAGE'!$B$17*SIN(RADIANS(A3))+'MAIN PAGE'!$G$3 -> 1.6e-05 | C3: 0.015 | D3: =(1/2)*'MAIN PAGE'!$B$2*'MAIN PAGE'!$B$5^2*B3*C3 -> 3.6123e-06 | E3: =D3 -> 3.6123e-06 | F3: =D3*COS(RADIANS(A3)) -> 3.6123e-06 | G3: 0 | H3: =(1/2)*'MAIN PAGE'!$B$2*'MAIN PAGE'!$B$5^2*'MAIN PAGE'!$G$6*G3 -> 0 | I3: =H3*SIN(RADIANS(90-A3)) -> 0 | J3: =H3*COS(RADIANS(90-A3)) -> 0 | K3: ='MAIN PAGE'!$G$29 -> 0.0045415395 | M3: =-(F3+J3) -> -3.6123e-06 | N3: =I3-E3-K3 -> -0.0045451518 | Q3: =('MAIN PAGE'!$B$26+'MAIN PAGE'!$B$25)*$H$3 -> 0 | R3: =('MAIN PAGE'!$B$25)*$E$3 -> 8.127675e-08 | S3: =-$Q$3+$R$3 -> 8.127675e-08 | V3: =('MAIN PAGE'!$B$25+'MAIN PAGE'!$B$24+'MAIN PAGE'!$B$21)*$H3 -> 0 | W3: =('MAIN PAGE'!$B$25+'MAIN PAGE'!$B$20)*$E3 -> 5.1475275e-07 | X3: =-$V3+$W3 -> 5.1475275e-07
A4: 1 | B4: ='MAIN PAGE'!$B$17*SIN(RADIANS(A4))+'MAIN PAGE'!$G$3 -> 0.00053957219 | C4: 0.016 | D4: =(1/2)*'MAIN PAGE'!$B$2*'MAIN PAGE'!$B$5^2*B4*C4 -> 0.00012993978 | E4: =D4*SIN(RADIANS(A4)) -> 2.2677618e-06 | F4: =D4*COS(RADIANS(A4)) -> 0.00012991999 | G4: 0.1 | H4: =(1/2)*'MAIN PAGE'!$B$2*'MAIN PAGE'!$B$5^2*'MAIN PAGE'!$G$6*G4 -> 0.00180615 | I4: =H4*SIN(RADIANS(90-A4)) -> 0.0018058749 | J4: =H4*COS(RADIANS(90-A4)) -> 3.1521664e-05 | K4: ='MAIN PAGE'!$G$29 -> 0.0045415395 | M4: =-(F4+J4) -> -0.00016144165 | N4: =I4-E4-K4 -> -0.0027379323 | Q4: =('MAIN PAGE'!$B$26+'MAIN PAGE'!$B$25)*H4 -> 4.7862975e-05 | R4: =('MAIN PAGE'!$B$25)*E4 -> 5.102464e-08 | S4: =-Q4+R4 -> -4.781195e-05 | V4: =('MAIN PAGE'!$B$25+'MAIN PAGE'!$B$24+'MAIN PAGE'!$B$21)*$H4 -> 0.00017609963 | W4: =('MAIN PAGE'!$B$25+'MAIN PAGE'!$B$20)*$E4 -> 3.2315605e-07 | X4: =-$V4+$W4 -> -0.00017577647
A5: 2 | B5: ='MAIN PAGE'!$B$17*SIN(RADIANS(A5))+'MAIN PAGE'!$G$3 -> 0.0010629849 | C5: 0.017 | D5: =(1/2)*'MAIN PAGE'!$B$2*'MAIN PAGE'!$B$5^2*B5*C5 -> 0.00027198728 | E5: =D5*SIN(RADIANS(A5)) -> 9.492219e-06 | F5: =D5*COS(RADIANS(A5)) -> 0.00027182159 | G5: 0.2 | H5: =(1/2)*'MAIN PAGE'!$B$2*'MAIN PAGE'!$B$5^2*'MAIN PAGE'!$G$6*G5 -> 0.0036123 | I5: =H5*SIN(RADIANS(90-A5)) -> 0.0036100995 | J5: =H5*COS(RADIANS(90-A5)) -> 0.00012606745 | K5: ='MAIN PAGE'!$G$29 -> 0.0045415395 | M5: =-(F5+J5) -> -0.00039788904 | N5: =I5-E5-K5 -> -0.00094093223 | Q5: =('MAIN PAGE'!$B$26+'MAIN PAGE'!$B$25)*H5 -> 9.572595e-05 | R5: =('MAIN PAGE'!$B$25)*E5 -> 2.1357493e-07 | S5: =-Q5+R5 -> -9.5512375e-05 | V5: =('MAIN PAGE'!$B$25+'MAIN PAGE'!$B$24+'MAIN PAGE'!$B$21)*$H5 -> 0.00035219925 | W5: =('MAIN PAGE'!$B$25+'MAIN PAGE'!$B$20)*$E5 -> 1.3526412e-06 | X5: =-$V5+$W5 -> -0.00035084661
A6: 3 | B6: ='MAIN PAGE'!$B$17*SIN(RADIANS(A6))+'MAIN PAGE'!$G$3 -> 0.0015860787 | C6: 0.019 | D6: =(1/2)*'MAIN PAGE'!$B$2*'MAIN PAGE'!$B$5^2*B6*C6 -> 0.00045357687 | E6: =D6*SIN(RADIANS(A6)) -> 2.3738379e-05 | F6: =D6*COS(RADIANS(A6)) -> 0.00045295526 | G6: 0.3 | H6: =(1/2)*'MAIN PAGE'!$B$2*'MAIN PAGE'!$B$5^2*'MAIN PAGE'!$G$6*G6 -> 0.00541845 | I6: =H6*SIN(RADIANS(90-A6)) -> 0.0054110242 | J6: =H6*COS(RADIANS(90-A6)) -> 0.00028357976 | K6: ='MAIN PAGE'!$G$29 -> 0.0045415395 | M6: =-(F6+J6) -> -0.00073653502 | N6: =I6-E6-K6 -> 0.00084574632 | Q6: =('MAIN PAGE'!$B$26+'MAIN PAGE'!$B$25)*H6 -> 0.00014358892 | R6: =('MAIN PAGE'!$B$25)*E6 -> 5.3411353e-07 | S6: =-Q6+R6 -> -0.00014305481 | V6: =('MAIN PAGE'!$B$25+'MAIN PAGE'!$B$24+'MAIN PAGE'!$B$21)*$H6 -> 0.00052829887 | W6: =('MAIN PAGE'!$B$25+'MAIN PAGE'!$B$20)*$E6 -> 3.382719e-06 | X6: =-$V6+$W6 -> -0.00052491616
A7: 4 | B7: ='MAIN PAGE'!$B$17*SIN(RADIANS(A7))+'MAIN PAGE'!$G$3 -> 0.0021086942 | C7: 0.022 | D7: =(1/2)*'MAIN PAGE'!$B$2*'MAIN PAGE'!$B$5^2*B7*C7 -> 0.00069824664 | E7: =D7*SIN(RADIANS(A7)) -> 4.8707224e-05 | F7: =D7*COS(RADIANS(A7)) -> 0.00069654575 | G7: 0.4 | H7: =(1/2)*'MAIN PAGE'!$B$2*'MAIN PAGE'!$B$5^2*'MAIN PAGE'!$G$6*G7 -> 0.0072246 | I7: =H7*SIN(RADIANS(90-A7)) -> 0.0072070012 | J7: =H7*COS(RADIANS(90-A7)) -> 0.00050396262 | K7: ='MAIN PAGE'!$G$29 -> 0.0045415395 | M7: =-(F7+J7) -> -0.0012005084 | N7: =I7-E7-K7 -> 0.0026167545 | Q7: =('MAIN PAGE'!$B$26+'MAIN PAGE'!$B$25)*H7 -> 0.0001914519 | R7: =('MAIN PAGE'!$B$25)*E7 -> 1.0959125e-06 | S7: =-Q7+R7 -> -0.00019035599 | V7: =('MAIN PAGE'!$B$25+'MAIN PAGE'!$B$24+'MAIN PAGE'!$B$21)*$H7 -> 0.0007043985 | W7: =('MAIN PAGE'!$B$25+'MAIN PAGE'!$B$20)*$E7 -> 6.9407794e-06 | X7: =-$V7+$W7 -> -0.00069745772
A8: 5 | B8: ='MAIN PAGE'!$B$17*SIN(RADIANS(A8))+'MAIN PAGE'!$G$3 -> 0.0026306723 | C8: 0.03 | D8: =(1/2)*'MAIN PAGE'!$B$2*'MAIN PAGE'!$B$5^2*B8*C8 -> 0.0011878472 | E8: =D8*SIN(RADIANS(A8)) -> 0.0001035277 | F8: =D8*COS(RADIANS(A8)) -> 0.0011833271 | G8: 0.5 | H8: =(1/2)*'MAIN PAGE'!$B$2*'MAIN PAGE'!$B$5^2*'MAIN PAGE'!$G$6*G8 -> 0.00903075 | I8: =H8*SIN(RADIANS(90-A8)) -> 0.0089963853 | J8: =H8*COS(RADIANS(90-A8)) -> 0.00078708172 | K8: ='MAIN PAGE'!$G$29 -> 0.0045415395 | M8: =-(F8+J8) -> -0.0019704088 | N8: =I8-E8-K8 -> 0.0043513181 | Q8: =('MAIN PAGE'!$B$26+'MAIN PAGE'!$B$25)*H8 -> 0.00023931487 | R8: =('MAIN PAGE'!$B$25)*E8 -> 2.3293733e-06 | S8: =-Q8+R8 -> -0.0002369855 | V8: =('MAIN PAGE'!$B$25+'MAIN PAGE'!$B$24+'MAIN PAGE'!$B$21)*$H8 -> 0.00088049812 | W8: =('MAIN PAGE'!$B$25+'MAIN PAGE'!$B$20)*$E8 -> 1.4752698e-05 | X8: =-$V8+$W8 -> -0.00086574543
A9: 6 | B9: ='MAIN PAGE'!$B$17*SIN(RADIANS(A9))+'MAIN PAGE'!$G$3 -> 0.0031518539 | C9: 0.04 | D9: =(1/2)*'MAIN PAGE'!$B$2*'MAIN PAGE'!$B$5^2*B9*C9 -> 0.0018975736 | E9: =D9*SIN(RADIANS(A9)) -> 0.00019835046 | F9: =D9*COS(RADIANS(A9)) -> 0.0018871785 | G9: 0.54 | H9: =(1/2)*'MAIN PAGE'!$B$2*'MAIN PAGE'!$B$5^2*'MAIN PAGE'!$G$6*G9 -> 0.00975321 | I9: =H9*SIN(RADIANS(90-A9)) -> 0.0096997809 | J9: =H9*COS(RADIANS(90-A9)) -> 0.0010194881 | K9: ='MAIN PAGE'!$G$29 -> 0.0045415395 | M9: =-(F9+J9) -> -0.0029066666 | N9: =I9-E9-K9 -> 0.0049598909 | Q9: =('MAIN PAGE'!$B$26+'MAIN PAGE'!$B$25)*H9 -> 0.00025846006 | R9: =('MAIN PAGE'!$B$25)*E9 -> 4.4628853e-06 | S9: =-Q9+R9 -> -0.00025399718 | V9: =('MAIN PAGE'!$B$25+'MAIN PAGE'!$B$24+'MAIN PAGE'!$B$21)*$H9 -> 0.00095093798 | W9: =('MAIN PAGE'!$B$25+'MAIN PAGE'!$B$20)*$E9 -> 2.826494e-05 | X9: =-$V9+$W9 -> -0.00092267303
A10: 7 | B10: ='MAIN PAGE'!$B$17*SIN(RADIANS(A10))+'MAIN PAGE'!$G$3 -> 0.0036720803 | C10: 0.05 | D10: =(1/2)*'MAIN PAGE'!$B$2*'MAIN PAGE'!$B$5^2*B10*C10 -> 0.0027634699 | E10: =D10*SIN(RADIANS(A10)) -> 0.00033678227 | F10: =D10*COS(RADIANS(A10)) -> 0.0027428714 | G10: 0.58 | H10: =(1/2)*'MAIN PAGE'!$B$2*'MAIN PAGE'!$B$5^2*'MAIN PAGE'!$G$6*G10 -> 0.01047567 | I10: =H10*SIN(RADIANS(90-A10)) -> 0.010397586 | J10: =H10*COS(RADIANS(90-A10)) -> 0.001276663 | K10: ='MAIN PAGE'!$G$29 -> 0.0045415395 | M10: =-(F10+J10) -> -0.0040195345 | N10: =I10-E10-K10 -> 0.0055192642 | Q10: =('MAIN PAGE'!$B$26+'MAIN PAGE'!$B$25)*H10 -> 0.00027760525 | R10: =('MAIN PAGE'!$B$25)*E10 -> 7.577601e-06 | S10: =-Q10+R10 -> -0.00027002765 | V10: =('MAIN PAGE'!$B$25+'MAIN PAGE'!$B$24+'MAIN PAGE'!$B$21)*$H10 -> 0.0010213778 | W10: =('MAIN PAGE'!$B$25+'MAIN PAGE'!$B$20)*$E10 -> 4.7991473e-05 | X10: =-$V10+$W10 -> -0.00097338635
A11: 8 | B11: ='MAIN PAGE'!$B$17*SIN(RADIANS(A11))+'MAIN PAGE'!$G$3 -> 0.004191193 | C11: 0.06 | D11: =(1/2)*'MAIN PAGE'!$B$2*'MAIN PAGE'!$B$5^2*B11*C11 -> 0.0037849616 | E11: =D11*SIN(RADIANS(A11)) -> 0.00052676485 | F11: =D11*COS(RADIANS(A11)) -> 0.0037481267 | G11: 0.62 | H11: =(1/2)*'MAIN PAGE'!$B$2*'MAIN PAGE'!$B$5^2*'MAIN PAGE'!$G$6*G11 -> 0.01119813 | I11: =H11*SIN(RADIANS(90-A11)) -> 0.011089151 | J11: =H11*COS(RADIANS(90-A11)) -> 0.0015584785 | K11: ='MAIN PAGE'!$G$29 -> 0.0045415395 | M11: =-(F11+J11) -> -0.0053066051 | N11: =I11-E11-K11 -> 0.0060208462 | Q11: =('MAIN PAGE'!$B$26+'MAIN PAGE'!$B$25)*H11 -> 0.00029675044 | R11: =('MAIN PAGE'!$B$25)*E11 -> 1.1852209e-05 | S11: =-Q11+R11 -> -0.00028489824 | V11: =('MAIN PAGE'!$B$25+'MAIN PAGE'!$B$24+'MAIN PAGE'!$B$21)*$H11 -> 0.0010918177 | W11: =('MAIN PAGE'!$B$25+'MAIN PAGE'!$B$20)*$E11 -> 7.5063991e-05 | X11: =-$V11+$W11 -> -0.0010167537
A12: 9 | B12: ='MAIN PAGE'!$B$17*SIN(RADIANS(A12))+'MAIN PAGE'!$G$3 -> 0.004709034 | C12: 0.07 | D12: =(1/2)*'MAIN PAGE'!$B$2*'MAIN PAGE'!$B$5^2*B12*C12 -> 0.0049613793 | E12: =D12*SIN(RADIANS(A12)) -> 0.00077613072 | F12: =D12*COS(RADIANS(A12)) -> 0.0049002965 | G12: 0.66 | H12: =(1/2)*'MAIN PAGE'!$B$2*'MAIN PAGE'!$B$5^2*'MAIN PAGE'!$G$6*G12 -> 0.01192059 | I12: =H12*SIN(RADIANS(90-A12)) -> 0.011773828 | J12: =H12*COS(RADIANS(90-A12)) -> 0.0018647911 | K12: ='MAIN PAGE'!$G$29 -> 0.0045415395 | M12: =-(F12+J12) -> -0.0067650876 | N12: =I12-E12-K12 -> 0.0064561575 | Q12: =('MAIN PAGE'!$B$26+'MAIN PAGE'!$B$25)*H12 -> 0.00031589563 | R12: =('MAIN PAGE'!$B$25)*E12 -> 1.7462941e-05 | S12: =-Q12+R12 -> -0.00029843269 | V12: =('MAIN PAGE'!$B$25+'MAIN PAGE'!$B$24+'MAIN PAGE'!$B$21)*$H12 -> 0.0011622575 | W12: =('MAIN PAGE'!$B$25+'MAIN PAGE'!$B$20)*$E12 -> 0.00011059863 | X12: =-$V12+$W12 -> -0.0010516589
A13: 10 | B13: ='MAIN PAGE'!$B$17*SIN(RADIANS(A13))+'MAIN PAGE'!$G$3 -> 0.0052254453 | C13: 0.08 | D13: =(1/2)*'MAIN PAGE'!$B$2*'MAIN PAGE'!$B$5^2*B13*C13 -> 0.0062919587 | E13: =D13*SIN(RADIANS(A13)) -> 0.0010925872 | F13: =D13*COS(RADIANS(A13)) -> 0.0061963697 | G13: 0.68 | H13: =(1/2)*'MAIN PAGE'!$B$2*'MAIN PAGE'!$B$5^2*'MAIN PAGE'!$G$6*G13 -> 0.01228182 | I13: =H13*SIN(RADIANS(90-A13)) -> 0.012095232 | J13: =H13*COS(RADIANS(90-A13)) -> 0.0021327157 | K13: ='MAIN PAGE'!$G$29 -> 0.0045415395 | M13: =-(F13+J13) -> -0.0083290854 | N13: =I13-E13-K13 -> 0.0064611049 | Q13: =('MAIN PAGE'!$B$26+'MAIN PAGE'!$B$25)*H13 -> 0.00032546823 | R13: =('MAIN PAGE'!$B$25)*E13 -> 2.4583211e-05 | S13: =-Q13+R13 -> -0.00030088502 | V13: =('MAIN PAGE'!$B$25+'MAIN PAGE'!$B$24+'MAIN PAGE'!$B$21)*$H13 -> 0.0011974774 | W13: =('MAIN PAGE'!$B$25+'MAIN PAGE'!$B$20)*$E13 -> 0.00015569367 | X13: =-$V13+$W13 -> -0.0010417838
A14: 11 | B14: ='MAIN PAGE'!$B$17*SIN(RADIANS(A14))+'MAIN PAGE'!$G$3 -> 0.0057402699 | C14: 0.09 | D14: =(1/2)*'MAIN PAGE'!$B$2*'MAIN PAGE'!$B$5^2*B14*C14 -> 0.0077758413 | E14: =D14*SIN(RADIANS(A14)) -> 0.0014837005 | F14: =D14*COS(RADIANS(A14)) -> 0.0076329772 | G14: 0.7 | H14: =(1/2)*'MAIN PAGE'!$B$2*'MAIN PAGE'!$B$5^2*'MAIN PAGE'!$G$6*G14 -> 0.01264305 | I14: =H14*SIN(RADIANS(90-A14)) -> 0.012410762 | J14: =H14*COS(RADIANS(90-A14)) -> 0.0024124077 | K14: ='MAIN PAGE'!$G$29 -> 0.0045415395 | M14: =-(F14+J14) -> -0.010045385 | N14: =I14-E14-K14 -> 0.0063855216 | Q14: =('MAIN PAGE'!$B$26+'MAIN PAGE'!$B$25)*H14 -> 0.00033504082 | R14: =('MAIN PAGE'!$B$25)*E14 -> 3.3383261e-05 | S14: =-Q14+R14 -> -0.00030165756 | V14: =('MAIN PAGE'!$B$25+'MAIN PAGE'!$B$24+'MAIN PAGE'!$B$21)*$H14 -> 0.0012326974 | W14: =('MAIN PAGE'!$B$25+'MAIN PAGE'!$B$20)*$E14 -> 0.00021142732 | X14: =-$V14+$W14 -> -0.0010212701
A15: 12 | B15: ='MAIN PAGE'!$B$17*SIN(RADIANS(A15))+'MAIN PAGE'!$G$3 -> 0.0062533507 | C15: 0.1 | D15: =(1/2)*'MAIN PAGE'!$B$2*'MAIN PAGE'!$B$5^2*B15*C15 -> 0.0094120745 | E15: =D15*SIN(RADIANS(A15)) -> 0.0019568803 | F15: =D15*COS(RADIANS(A15)) -> 0.0092063981 | G15: 0.68 | H15: =(1/2)*'MAIN PAGE'!$B$2*'MAIN PAGE'!$B$5^2*'MAIN PAGE'!$G$6*G15 -> 0.01228182 | I15: =H15*SIN(RADIANS(90-A15)) -> 0.012013433 | J15: =H15*COS(RADIANS(90-A15)) -> 0.002553534 | K15: ='MAIN PAGE'!$G$29 -> 0.0045415395 | M15: =-(F15+J15) -> -0.011759932 | N15: =I15-E15-K15 -> 0.0055150129 | Q15: =('MAIN PAGE'!$B$26+'MAIN PAGE'!$B$25)*H15 -> 0.00032546823 | R15: =('MAIN PAGE'!$B$25)*E15 -> 4.4029807e-05 | S15: =-Q15+R15 -> -0.00028143842 | V15: =('MAIN PAGE'!$B$25+'MAIN PAGE'!$B$24+'MAIN PAGE'!$B$21)*$H15 -> 0.0011974774 | W15: =('MAIN PAGE'!$B$25+'MAIN PAGE'!$B$20)*$E15 -> 0.00027885545 | X15: =-$V15+$W15 -> -0.000918622

Sheet Wing Flap (rigid body)
A1: Flapping Data | B1: position (y) | C1: velocity (v) | D1: acceleration (a) | E1: acc (α) | F1: torque (τ) | G1: TOTAL (for 2 wings) | I1: Wing Calculations | K1: **note flapping inputs are on first page
A2: sec | B2: m | C2: m/s | D2: m/s^2 | E2: rad/s^2 | F2: Nm | I2: **estimate as rectangle
A3: 0 | B3: ='MAIN PAGE'!$B$13*COS(2*PI()*'MAIN PAGE'!$B$12*A3) -> 0.04 | C3: =-'MAIN PAGE'!$B$13*(2*PI()*'MAIN PAGE'!$B$12)*SIN(2*PI()*'MAIN PAGE'!$B$12*'Wing Flap (rigid body)'!A3) -> 0 | D3: =-'MAIN PAGE'!$B$13*((2*PI()*'MAIN PAGE'!$B$12)^2)*COS(2*PI()*'MAIN PAGE'!$B$12*'Wing Flap (rigid body)'!A3) -> -157.91367 | E3: =D3/$J$5 -> -1579.1367 | F3: =E3*$J$13 -> -0.013455561 | G3: =F3*2 -> -0.026911121
A4: 0.01 | B4: ='MAIN PAGE'!$B$13*COS(2*PI()*'MAIN PAGE'!$B$12*A4) -> 0.03236068 | C4: =-'MAIN PAGE'!$B$13*(2*PI()*'MAIN PAGE'!$B$12)*SIN(2*PI()*'MAIN PAGE'!$B$12*'Wing Flap (rigid body)'!A4) -> -1.4772655 | D4: =-'MAIN PAGE'!$B$13*(2*PI()*'MAIN PAGE'!$B$12)^2*COS(2*PI()*'MAIN PAGE'!$B$12*'Wing Flap (rigid body)'!A4) -> -127.75484 | E4: =D4/$J$5 -> -1277.5484 | F4: =E4*$J$13 -> -0.010885777 | G4: =F4*2 -> -0.021771554 | I4: chord | J4: 0.03 | K4: m | L4: =J4*39.37 -> 1.1811 | M4: in
A5: =A4+0.005 -> 0.015 | B5: ='MAIN PAGE'!$B$13*COS(2*PI()*'MAIN PAGE'!$B$12*A5) -> 0.02351141 | C5: =-'MAIN PAGE'!$B$13*(2*PI()*'MAIN PAGE'!$B$12)*SIN(2*PI()*'MAIN PAGE'!$B$12*'Wing Flap (rigid body)'!A5) -> -2.0332815 | D5: =-'MAIN PAGE'!$B$13*(2*PI()*'MAIN PAGE'!$B$12)^2*COS(2*PI()*'MAIN PAGE'!$B$12*'Wing Flap (rigid body)'!A5) -> -92.819327 | E5: =D5/$J$5 -> -928.19327 | F5: =E5*$J$13 -> -0.0079089801 | G5: =F5*2 -> -0.01581796 | I5: span | J5: 0.1 | K5: m | L5: =J5*39.37 -> 3.937 | M5: in
A6: =A5+0.005 -> 0.02 | B6: ='MAIN PAGE'!$B$13*COS(2*PI()*'MAIN PAGE'!$B$12*A6) -> 0.01236068 | C6: =-'MAIN PAGE'!$B$13*(2*PI()*'MAIN PAGE'!$B$12)*SIN(2*PI()*'MAIN PAGE'!$B$12*'Wing Flap (rigid body)'!A6) -> -2.3902657 | D6: =-'MAIN PAGE'!$B$13*(2*PI()*'MAIN PAGE'!$B$12)^2*COS(2*PI()*'MAIN PAGE'!$B$12*'Wing Flap (rigid body)'!A6) -> -48.798008 | E6: =D6/$J$5 -> -487.98008 | F6: =E6*$J$13 -> -0.0041579969 | G6: =F6*2 -> -0.0083159938 | I6: area wing | J6: =J5*J4 -> 0.003 | K6: m
A7: =A6+0.005 -> 0.025 | B7: ='MAIN PAGE'!$B$13*COS(2*PI()*'MAIN PAGE'!$B$12*A7) -> 2.4502969e-18 | C7: =-'MAIN PAGE'!$B$13*(2*PI()*'MAIN PAGE'!$B$12)*SIN(2*PI()*'MAIN PAGE'!$B$12*'Wing Flap (rigid body)'!A7) -> -2.5132741 | D7: =-'MAIN PAGE'!$B$13*(2*PI()*'MAIN PAGE'!$B$12)^2*COS(2*PI()*'MAIN PAGE'!$B$12*'Wing Flap (rigid body)'!A7) -> -9.6733845e-15 | E7: =D7/$J$5 -> -9.6733845e-14 | F7: =E7*$J$13 -> -8.2425297e-19 | G7: =F7*2 -> -1.6485059e-18 | I7: thickness | J7: 0.001 | K7: m
A8: =A7+0.005 -> 0.03 | B8: ='MAIN PAGE'!$B$13*COS(2*PI()*'MAIN PAGE'!$B$12*A8) -> -0.01236068 | C8: =-'MAIN PAGE'!$B$13*(2*PI()*'MAIN PAGE'!$B$12)*SIN(2*PI()*'MAIN PAGE'!$B$12*'Wing Flap (rigid body)'!A8) -> -2.3902657 | D8: =-'MAIN PAGE'!$B$13*(2*PI()*'MAIN PAGE'!$B$12)^2*COS(2*PI()*'MAIN PAGE'!$B$12*'Wing Flap (rigid body)'!A8) -> 48.798008 | E8: =D8/$J$5 -> 487.98008 | F8: =E8*$J$13 -> 0.0041579969 | G8: =F8*2 -> 0.0083159938 | I8: volume | J8: =J6*J7 -> 3e-06 | K8: m^2
A9: =A8+0.005 -> 0.035 | B9: ='MAIN PAGE'!$B$13*COS(2*PI()*'MAIN PAGE'!$B$12*A9) -> -0.02351141 | C9: =-'MAIN PAGE'!$B$13*(2*PI()*'MAIN PAGE'!$B$12)*SIN(2*PI()*'MAIN PAGE'!$B$12*'Wing Flap (rigid body)'!A9) -> -2.0332815 | D9: =-'MAIN PAGE'!$B$13*(2*PI()*'MAIN PAGE'!$B$12)^2*COS(2*PI()*'MAIN PAGE'!$B$12*'Wing Flap (rigid body)'!A9) -> 92.819327 | E9: =D9/$J$5 -> 928.19327 | F9: =E9*$J$13 -> 0.0079089801 | G9: =F9*2 -> 0.01581796 | I9: density material
A10: =A9+0.005 -> 0.04 | B10: ='MAIN PAGE'!$B$13*COS(2*PI()*'MAIN PAGE'!$B$12*A10) -> -0.03236068 | C10: =-'MAIN PAGE'!$B$13*(2*PI()*'MAIN PAGE'!$B$12)*SIN(2*PI()*'MAIN PAGE'!$B$12*'Wing Flap (rigid body)'!A10) -> -1.4772655 | D10: =-'MAIN PAGE'!$B$13*(2*PI()*'MAIN PAGE'!$B$12)^2*COS(2*PI()*'MAIN PAGE'!$B$12*'Wing Flap (rigid body)'!A10) -> 127.75484 | E10: =D10/$J$5 -> 1277.5484 | F10: =E10*$J$13 -> 0.010885777 | G10: =F10*2 -> 0.021771554 | I10: mass | J10: 0.0025 | K10: kg | L10: =J10*1000 -> 2.5 | M10: g
A11: =A10+0.005 -> 0.045 | B11: ='MAIN PAGE'!$B$13*COS(2*PI()*'MAIN PAGE'!$B$12*A11) -> -0.038042261 | C11: =-'MAIN PAGE'!$B$13*(2*PI()*'MAIN PAGE'!$B$12)*SIN(2*PI()*'MAIN PAGE'!$B$12*'Wing Flap (rigid body)'!A11) -> -0.77664442 | D11: =-'MAIN PAGE'!$B$13*(2*PI()*'MAIN PAGE'!$B$12)^2*COS(2*PI()*'MAIN PAGE'!$B$12*'Wing Flap (rigid body)'!A11) -> 150.18483 | E11: =D11/$J$5 -> 1501.8483 | F11: =E11*$J$13 -> 0.012796999 | G11: =F11*2 -> 0.025593997
A12: =A11+0.005 -> 0.05 | B12: ='MAIN PAGE'!$B$13*COS(2*PI()*'MAIN PAGE'!$B$12*A12) -> -0.04 | C12: =-'MAIN PAGE'!$B$13*(2*PI()*'MAIN PAGE'!$B$12)*SIN(2*PI()*'MAIN PAGE'!$B$12*'Wing Flap (rigid body)'!A12) -> -1.4240313e-15 | D12: =-'MAIN PAGE'!$B$13*(2*PI()*'MAIN PAGE'!$B$12)^2*COS(2*PI()*'MAIN PAGE'!$B$12*'Wing Flap (rigid body)'!A12) -> 157.91367 | E12: =D12/$J$5 -> 1579.1367 | F12: =E12*$J$13 -> 0.013455561 | G12: =F12*2 -> 0.026911121 | I12: Inertia center | J12: =(1/12)*J10*(J4^2+J5^2) -> 2.2708333e-06
A13: =A12+0.005 -> 0.055 | B13: ='MAIN PAGE'!$B$13*COS(2*PI()*'MAIN PAGE'!$B$12*A13) -> -0.038042261 | C13: =-'MAIN PAGE'!$B$13*(2*PI()*'MAIN PAGE'!$B$12)*SIN(2*PI()*'MAIN PAGE'!$B$12*'Wing Flap (rigid body)'!A13) -> 0.77664442 | D13: =-'MAIN PAGE'!$B$13*(2*PI()*'MAIN PAGE'!$B$12)^2*COS(2*PI()*'MAIN PAGE'!$B$12*'Wing Flap (rigid body)'!A13) -> 150.18483 | E13: =D13/$J$5 -> 1501.8483 | F13: =E13*$J$13 -> 0.012796999 | G13: =F13*2 -> 0.025593997 | I13: Inertia edge | J13: =J12+(J10*((1/2)*J5)^2) -> 8.5208333e-06 | K13: kg.m^2 | L13: check?? | M13: =(1/3)*J10*J5^2 -> 8.3333333e-06
A14: =A13+0.005 -> 0.06 | B14: ='MAIN PAGE'!$B$13*COS(2*PI()*'MAIN PAGE'!$B$12*A14) -> -0.03236068 | C14: =-'MAIN PAGE'!$B$13*(2*PI()*'MAIN PAGE'!$B$12)*SIN(2*PI()*'MAIN PAGE'!$B$12*'Wing Flap (rigid body)'!A14) -> 1.4772655 | D14: =-'MAIN PAGE'!$B$13*(2*PI()*'MAIN PAGE'!$B$12)^2*COS(2*PI()*'MAIN PAGE'!$B$12*'Wing Flap (rigid body)'!A14) -> 127.75484 | E14: =D14/$J$5 -> 1277.5484 | F14: =E14*$J$13 -> 0.010885777 | G14: =F14*2 -> 0.021771554
A15: =A14+0.005 -> 0.065 | B15: ='MAIN PAGE'!$B$13*COS(2*PI()*'MAIN PAGE'!$B$12*A15) -> -0.02351141 | C15: =-'MAIN PAGE'!$B$13*(2*PI()*'MAIN PAGE'!$B$12)*SIN(2*PI()*'MAIN PAGE'!$B$12*'Wing Flap (rigid body)'!A15) -> 2.0332815 | D15: =-'MAIN PAGE'!$B$13*(2*PI()*'MAIN PAGE'!$B$12)^2*COS(2*PI()*'MAIN PAGE'!$B$12*'Wing Flap (rigid body)'!A15) -> 92.819327 | E15: =D15/$J$5 -> 928.19327 | F15: =E15*$J$13 -> 0.0079089801 | G15: =F15*2 -> 0.01581796
A16: =A15+0.005 -> 0.07 | B16: ='MAIN PAGE'!$B$13*COS(2*PI()*'MAIN PAGE'!$B$12*A16) -> -0.01236068 | C16: =-'MAIN PAGE'!$B$13*(2*PI()*'MAIN PAGE'!$B$12)*SIN(2*PI()*'MAIN PAGE'!$B$12*'Wing Flap (rigid body)'!A16) -> 2.3902657 | D16: =-'MAIN PAGE'!$B$13*(2*PI()*'MAIN PAGE'!$B$12)^2*COS(2*PI()*'MAIN PAGE'!$B$12*'Wing Flap (rigid body)'!A16) -> 48.798008 | E16: =D16/$J$5 -> 487.98008 | F16: =E16*$J$13 -> 0.0041579969 | G16: =F16*2 -> 0.0083159938
A17: =A16+0.005 -> 0.075 | B17: ='MAIN PAGE'!$B$13*COS(2*PI()*'MAIN PAGE'!$B$12*A17) -> -7.3508907e-18 | C17: =-'MAIN PAGE'!$B$13*(2*PI()*'MAIN PAGE'!$B$12)*SIN(2*PI()*'MAIN PAGE'!$B$12*'Wing Flap (rigid body)'!A17) -> 2.5132741 | D17: =-'MAIN PAGE'!$B$13*(2*PI()*'MAIN PAGE'!$B$12)^2*COS(2*PI()*'MAIN PAGE'!$B$12*'Wing Flap (rigid body)'!A17) -> 2.9020153e-14 | E17: =D17/$J$5 -> 2.9020153e-13 | F17: =E17*$J$13 -> 2.4727589e-18 | G17: =F17*2 -> 4.9455178e-18
A18: =A17+0.005 -> 0.08 | B18: ='MAIN PAGE'!$B$13*COS(2*PI()*'MAIN PAGE'!$B$12*A18) -> 0.01236068 | C18: =-'MAIN PAGE'!$B$13*(2*PI()*'MAIN PAGE'!$B$12)*SIN(2*PI()*'MAIN PAGE'!$B$12*'Wing Flap (rigid body)'!A18) -> 2.3902657 | D18: =-'MAIN PAGE'!$B$13*(2*PI()*'MAIN PAGE'!$B$12)^2*COS(2*PI()*'MAIN PAGE'!$B$12*'Wing Flap (rigid body)'!A18) -> -48.798008 | E18: =D18/$J$5 -> -487.98008 | F18: =E18*$J$13 -> -0.0041579969 | G18: =F18*2 -> -0.0083159938
A19: =A18+0.005 -> 0.085 | B19: ='MAIN PAGE'!$B$13*COS(2*PI()*'MAIN PAGE'!$B$12*A19) -> 0.02351141 | C19: =-'MAIN PAGE'!$B$13*(2*PI()*'MAIN PAGE'!$B$12)*SIN(2*PI()*'MAIN PAGE'!$B$12*'Wing Flap (rigid body)'!A19) -> 2.0332815 | D19: =-'MAIN PAGE'!$B$13*(2*PI()*'MAIN PAGE'!$B$12)^2*COS(2*PI()*'MAIN PAGE'!$B$12*'Wing Flap (rigid body)'!A19) -> -92.819327 | E19: =D19/$J$5 -> -928.19327 | F19: =E19*$J$13 -> -0.0079089801 | G19: =F19*2 -> -0.01581796
A20: =A19+0.005 -> 0.09 | B20: ='MAIN PAGE'!$B$13*COS(2*PI()*'MAIN PAGE'!$B$12*A20) -> 0.03236068 | C20: =-'MAIN PAGE'!$B$13*(2*PI()*'MAIN PAGE'!$B$12)*SIN(2*PI()*'MAIN PAGE'!$B$12*'Wing Flap (rigid body)'!A20) -> 1.4772655 | D20: =-'MAIN PAGE'!$B$13*(2*PI()*'MAIN PAGE'!$B$12)^2*COS(2*PI()*'MAIN PAGE'!$B$12*'Wing Flap (rigid body)'!A20) -> -127.75484 | E20: =D20/$J$5 -> -1277.5484 | F20: =E20*$J$13 -> -0.010885777 | G20: =F20*2 -> -0.021771554
A21: =A20+0.005 -> 0.095 | B21: ='MAIN PAGE'!$B$13*COS(2*PI()*'MAIN PAGE'!$B$12*A21) -> 0.038042261 | C21: =-'MAIN PAGE'!$B$13*(2*PI()*'MAIN PAGE'!$B$12)*SIN(2*PI()*'MAIN PAGE'!$B$12*'Wing Flap (rigid body)'!A21) -> 0.77664442 | D21: =-'MAIN PAGE'!$B$13*(2*PI()*'MAIN PAGE'!$B$12)^2*COS(2*PI()*'MAIN PAGE'!$B$12*'Wing Flap (rigid body)'!A21) -> -150.18483 | E21: =D21/$J$5 -> -1501.8483 | F21: =E21*$J$13 -> -0.012796999 | G21: =F21*2 -> -0.025593997
A22: =A21+0.005 -> 0.1 | B22: ='MAIN PAGE'!$B$13*COS(2*PI()*'MAIN PAGE'!$B$12*A22) -> 0.04 | C22: =-'MAIN PAGE'!$B$13*(2*PI()*'MAIN PAGE'!$B$12)*SIN(2*PI()*'MAIN PAGE'!$B$12*'Wing Flap (rigid body)'!A22) -> -1.6164091e-15 | D22: =-'MAIN PAGE'!$B$13*(2*PI()*'MAIN PAGE'!$B$12)^2*COS(2*PI()*'MAIN PAGE'!$B$12*'Wing Flap (rigid body)'!A22) -> -157.91367 | E22: =D22/$J$5 -> -1579.1367 | F22: =E22*$J$13 -> -0.013455561 | G22: =F22*2 -> -0.026911121
A23: **for 10 hz shows one period of motion estimated using cos wave

Sheet Wing Flap (particle)
A1: Flapping Data | B1: position (y) | C1: velocity (v) | D1: acceleration (a) | E1: torque (τ) | F1: TOTAL | H1: Wing Calculations | J1: **note flapping inputs are on first page
A2: sec | B2: m | C2: m/s | D2: m/s^2 | E2: Nm | H2: **estimate as rectangle
A3: 0 | B3: ='MAIN PAGE'!$B$13*COS(2*PI()*'MAIN PAGE'!$B$12*A3) -> 0.04 | C3: =-'MAIN PAGE'!$B$13*(2*PI()*'MAIN PAGE'!$B$12)*SIN(2*PI()*'MAIN PAGE'!$B$12*'Wing Flap (particle)'!A3) -> 0 | D3: =-'MAIN PAGE'!$B$13*((2*PI()*'MAIN PAGE'!$B$12)^2)*COS(2*PI()*'MAIN PAGE'!$B$12*'Wing Flap (particle)'!A3) -> -157.91367 | E3: =D3*$I$10 -> -0.39478418 | F3: =E3*2 -> -0.78956835
A4: 0.01 | B4: ='MAIN PAGE'!$B$13*COS(2*PI()*'MAIN PAGE'!$B$12*A4) -> 0.03236068 | C4: =-'MAIN PAGE'!$B$13*(2*PI()*'MAIN PAGE'!$B$12)*SIN(2*PI()*'MAIN PAGE'!$B$12*'Wing Flap (particle)'!A4) -> -1.4772655 | D4: =-'MAIN PAGE'!$B$13*(2*PI()*'MAIN PAGE'!$B$12)^2*COS(2*PI()*'MAIN PAGE'!$B$12*'Wing Flap (particle)'!A4) -> -127.75484 | E4: =D4*$I$10 -> -0.31938711 | F4: =E4*2 -> -0.63877422 | H4: chord | I4: 0.03 | J4: m | K4: =I4*39.37 -> 1.1811 | L4: in
A5: =A4+0.005 -> 0.015 | B5: ='MAIN PAGE'!$B$13*COS(2*PI()*'MAIN PAGE'!$B$12*A5) -> 0.02351141 | C5: =-'MAIN PAGE'!$B$13*(2*PI()*'MAIN PAGE'!$B$12)*SIN(2*PI()*'MAIN PAGE'!$B$12*'Wing Flap (particle)'!A5) -> -2.0332815 | D5: =-'MAIN PAGE'!$B$13*(2*PI()*'MAIN PAGE'!$B$12)^2*COS(2*PI()*'MAIN PAGE'!$B$12*'Wing Flap (particle)'!A5) -> -92.819327 | E5: =D5*$I$10 -> -0.23204832 | F5: =E5*2 -> -0.46409663 | H5: span | I5: 0.1 | J5: m | K5: =I5*39.37 -> 3.937 | L5: in
A6: =A5+0.005 -> 0.02 | B6: ='MAIN PAGE'!$B$13*COS(2*PI()*'MAIN PAGE'!$B$12*A6) -> 0.01236068 | C6: =-'MAIN PAGE'!$B$13*(2*PI()*'MAIN PAGE'!$B$12)*SIN(2*PI()*'MAIN PAGE'!$B$12*'Wing Flap (particle)'!A6) -> -2.3902657 | D6: =-'MAIN PAGE'!$B$13*(2*PI()*'MAIN PAGE'!$B$12)^2*COS(2*PI()*'MAIN PAGE'!$B$12*'Wing Flap (particle)'!A6) -> -48.798008 | E6: =D6*$I$10 -> -0.12199502 | F6: =E6*2 -> -0.24399004 | H6: area wing | I6: =I5*I4 -> 0.003 | J6: m
A7: =A6+0.005 -> 0.025 | B7: ='MAIN PAGE'!$B$13*COS(2*PI()*'MAIN PAGE'!$B$12*A7) -> 2.4502969e-18 | C7: =-'MAIN PAGE'!$B$13*(2*PI()*'MAIN PAGE'!$B$12)*SIN(2*PI()*'MAIN PAGE'!$B$12*'Wing Flap (particle)'!A7) -> -2.5132741 | D7: =-'MAIN PAGE'!$B$13*(2*PI()*'MAIN PAGE'!$B$12)^2*COS(2*PI()*'MAIN PAGE'!$B$12*'Wing Flap (particle)'!A7) -> -9.6733845e-15 | E7: =D7*$I$10 -> -2.4183461e-17 | F7: =E7*2 -> -4.8366922e-17 | H7: thickness | I7: 0.001 | J7: m
A8: =A7+0.005 -> 0.03 | B8: ='MAIN PAGE'!$B$13*COS(2*PI()*'MAIN PAGE'!$B$12*A8) -> -0.01236068 | C8: =-'MAIN PAGE'!$B$13*(2*PI()*'MAIN PAGE'!$B$12)*SIN(2*PI()*'MAIN PAGE'!$B$12*'Wing Flap (particle)'!A8) -> -2.3902657 | D8: =-'MAIN PAGE'!$B$13*(2*PI()*'MAIN PAGE'!$B$12)^2*COS(2*PI()*'MAIN PAGE'!$B$12*'Wing Flap (particle)'!A8) -> 48.798008 | E8: =D8*$I$10 -> 0.12199502 | F8: =E8*2 -> 0.24399004 | H8: volume | I8: =I6*I7 -> 3e-06 | J8: m^2
A9: =A8+0.005 -> 0.035 | B9: ='MAIN PAGE'!$B$13*COS(2*PI()*'MAIN PAGE'!$B$12*A9) -> -0.02351141 | C9: =-'MAIN PAGE'!$B$13*(2*PI()*'MAIN PAGE'!$B$12)*SIN(2*PI()*'MAIN PAGE'!$B$12*'Wing Flap (particle)'!A9) -> -2.0332815 | D9: =-'MAIN PAGE'!$B$13*(2*PI()*'MAIN PAGE'!$B$12)^2*COS(2*PI()*'MAIN PAGE'!$B$12*'Wing Flap (particle)'!A9) -> 92.819327 | E9: =D9*$I$10 -> 0.23204832 | F9: =E9*2 -> 0.46409663 | H9: density material
A10: =A9+0.005 -> 0.04 | B10: ='MAIN PAGE'!$B$13*COS(2*PI()*'MAIN PAGE'!$B$12*A10) -> -0.03236068 | C10: =-'MAIN PAGE'!$B$13*(2*PI()*'MAIN PAGE'!$B$12)*SIN(2*PI()*'MAIN PAGE'!$B$12*'Wing Flap (particle)'!A10) -> -1.4772655 | D10: =-'MAIN PAGE'!$B$13*(2*PI()*'MAIN PAGE'!$B$12)^2*COS(2*PI()*'MAIN PAGE'!$B$12*'Wing Flap (particle)'!A10) -> 127.75484 | E10: =D10*$I$10 -> 0.31938711 | F10: =E10*2 -> 0.63877422 | H10: mass | I10: 0.0025 | J10: kg | K10: =I10*1000 -> 2.5 | L10: g
A11: =A10+0.005 -> 0.045 | B11: ='MAIN PAGE'!$B$13*COS(2*PI()*'MAIN PAGE'!$B$12*A11) -> -0.038042261 | C11: =-'MAIN PAGE'!$B$13*(2*PI()*'MAIN PAGE'!$B$12)*SIN(2*PI()*'MAIN PAGE'!$B$12*'Wing Flap (particle)'!A11) -> -0.77664442 | D11: =-'MAIN PAGE'!$B$13*(2*PI()*'MAIN PAGE'!$B$12)^2*COS(2*PI()*'MAIN PAGE'!$B$12*'Wing Flap (particle)'!A11) -> 150.18483 | E11: =D11*$I$10 -> 0.37546206 | F11: =E11*2 -> 0.75092413
A12: =A11+0.005 -> 0.05 | B12: ='MAIN PAGE'!$B$13*COS(2*PI()*'MAIN PAGE'!$B$12*A12) -> -0.04 | C12: =-'MAIN PAGE'!$B$13*(2*PI()*'MAIN PAGE'!$B$12)*SIN(2*PI()*'MAIN PAGE'!$B$12*'Wing Flap (particle)'!A12) -> -1.4240313e-15 | D12: =-'MAIN PAGE'!$B$13*(2*PI()*'MAIN PAGE'!$B$12)^2*COS(2*PI()*'MAIN PAGE'!$B$12*'Wing Flap (particle)'!A12) -> 157.91367 | E12: =D12*$I$10 -> 0.39478418 | F12: =E12*2 -> 0.78956835 | H12: Inertia center | I12: =(1/12)*I10*(I4^2+I5^2) -> 2.2708333e-06
A13: =A12+0.005 -> 0.055 | B13: ='MAIN PAGE'!$B$13*COS(2*PI()*'MAIN PAGE'!$B$12*A13) -> -0.038042261 | C13: =-'MAIN PAGE'!$B$13*(2*PI()*'MAIN PAGE'!$B$12)*SIN(2*PI()*'MAIN PAGE'!$B$12*'Wing Flap (particle)'!A13) -> 0.77664442 | D13: =-'MAIN PAGE'!$B$13*(2*PI()*'MAIN PAGE'!$B$12)^2*COS(2*PI()*'MAIN PAGE'!$B$12*'Wing Flap (particle)'!A13) -> 150.18483 | E13: =D13*$I$10 -> 0.37546206 | F13: =E13*2 -> 0.75092413 | H13: Inertia edge | I13: =I12+(I10*((1/2)*I5)^2) -> 8.5208333e-06 | J13: kg.m^2 | K13: check?? | L13: =(1/3)*I10*I5^2 -> 8.3333333e-06
A14: =A13+0.005 -> 0.06 | B14: ='MAIN PAGE'!$B$13*COS(2*PI()*'MAIN PAGE'!$B$12*A14) -> -0.03236068 | C14: =-'MAIN PAGE'!$B$13*(2*PI()*'MAIN PAGE'!$B$12)*SIN(2*PI()*'MAIN PAGE'!$B$12*'Wing Flap (particle)'!A14) -> 1.4772655 | D14: =-'MAIN PAGE'!$B$13*(2*PI()*'MAIN PAGE'!$B$12)^2*COS(2*PI()*'MAIN PAGE'!$B$12*'Wing Flap (particle)'!A14) -> 127.75484 | E14: =D14*$I$10 -> 0.31938711 | F14: =E14*2 -> 0.63877422
A15: =A14+0.005 -> 0.065 | B15: ='MAIN PAGE'!$B$13*COS(2*PI()*'MAIN PAGE'!$B$12*A15) -> -0.02351141 | C15: =-'MAIN PAGE'!$B$13*(2*PI()*'MAIN PAGE'!$B$12)*SIN(2*PI()*'MAIN PAGE'!$B$12*'Wing Flap (particle)'!A15) -> 2.0332815 | D15: =-'MAIN PAGE'!$B$13*(2*PI()*'MAIN PAGE'!$B$12)^2*COS(2*PI()*'MAIN PAGE'!$B$12*'Wing Flap (particle)'!A15) -> 92.819327 | E15: =D15*$I$10 -> 0.23204832 | F15: =E15*2 -> 0.46409663
A16: =A15+0.005 -> 0.07 | B16: ='MAIN PAGE'!$B$13*COS(2*PI()*'MAIN PAGE'!$B$12*A16) -> -0.01236068 | C16: =-'MAIN PAGE'!$B$13*(2*PI()*'MAIN PAGE'!$B$12)*SIN(2*PI()*'MAIN PAGE'!$B$12*'Wing Flap (particle)'!A16) -> 2.3902657 | D16: =-'MAIN PAGE'!$B$13*(2*PI()*'MAIN PAGE'!$B$12)^2*COS(2*PI()*'MAIN PAGE'!$B$12*'Wing Flap (particle)'!A16) -> 48.798008 | E16: =D16*$I$10 -> 0.12199502 | F16: =E16*2 -> 0.24399004
A17: =A16+0.005 -> 0.075 | B17: ='MAIN PAGE'!$B$13*COS(2*PI()*'MAIN PAGE'!$B$12*A17) -> -7.3508907e-18 | C17: =-'MAIN PAGE'!$B$13*(2*PI()*'MAIN PAGE'!$B$12)*SIN(2*PI()*'MAIN PAGE'!$B$12*'Wing Flap (particle)'!A17) -> 2.5132741 | D17: =-'MAIN PAGE'!$B$13*(2*PI()*'MAIN PAGE'!$B$12)^2*COS(2*PI()*'MAIN PAGE'!$B$12*'Wing Flap (particle)'!A17) -> 2.9020153e-14 | E17: =D17*$I$10 -> 7.2550383e-17 | F17: =E17*2 -> 1.4510077e-16
A18: =A17+0.005 -> 0.08 | B18: ='MAIN PAGE'!$B$13*COS(2*PI()*'MAIN PAGE'!$B$12*A18) -> 0.01236068 | C18: =-'MAIN PAGE'!$B$13*(2*PI()*'MAIN PAGE'!$B$12)*SIN(2*PI()*'MAIN PAGE'!$B$12*'Wing Flap (particle)'!A18) -> 2.3902657 | D18: =-'MAIN PAGE'!$B$13*(2*PI()*'MAIN PAGE'!$B$12)^2*COS(2*PI()*'MAIN PAGE'!$B$12*'Wing Flap (particle)'!A18) -> -48.798008 | E18: =D18*$I$10 -> -0.12199502 | F18: =E18*2 -> -0.24399004
A19: =A18+0.005 -> 0.085 | B19: ='MAIN PAGE'!$B$13*COS(2*PI()*'MAIN PAGE'!$B$12*A19) -> 0.02351141 | C19: =-'MAIN PAGE'!$B$13*(2*PI()*'MAIN PAGE'!$B$12)*SIN(2*PI()*'MAIN PAGE'!$B$12*'Wing Flap (particle)'!A19) -> 2.0332815 | D19: =-'MAIN PAGE'!$B$13*(2*PI()*'MAIN PAGE'!$B$12)^2*COS(2*PI()*'MAIN PAGE'!$B$12*'Wing Flap (particle)'!A19) -> -92.819327 | E19: =D19*$I$10 -> -0.23204832 | F19: =E19*2 -> -0.46409663
A20: =A19+0.005 -> 0.09 | B20: ='MAIN PAGE'!$B$13*COS(2*PI()*'MAIN PAGE'!$B$12*A20) -> 0.03236068 | C20: =-'MAIN PAGE'!$B$13*(2*PI()*'MAIN PAGE'!$B$12)*SIN(2*PI()*'MAIN PAGE'!$B$12*'Wing Flap (particle)'!A20) -> 1.4772655 | D20: =-'MAIN PAGE'!$B$13*(2*PI()*'MAIN PAGE'!$B$12)^2*COS(2*PI()*'MAIN PAGE'!$B$12*'Wing Flap (particle)'!A20) -> -127.75484 | E20: =D20*$I$10 -> -0.31938711 | F20: =E20*2 -> -0.63877422
A21: =A20+0.005 -> 0.095 | B21: ='MAIN PAGE'!$B$13*COS(2*PI()*'MAIN PAGE'!$B$12*A21) -> 0.038042261 | C21: =-'MAIN PAGE'!$B$13*(2*PI()*'MAIN PAGE'!$B$12)*SIN(2*PI()*'MAIN PAGE'!$B$12*'Wing Flap (particle)'!A21) -> 0.77664442 | D21: =-'MAIN PAGE'!$B$13*(2*PI()*'MAIN PAGE'!$B$12)^2*COS(2*PI()*'MAIN PAGE'!$B$12*'Wing Flap (particle)'!A21) -> -150.18483 | E21: =D21*$I$10 -> -0.37546206 | F21: =E21*2 -> -0.75092413
A22: =A21+0.005 -> 0.1 | B22: ='MAIN PAGE'!$B$13*COS(2*PI()*'MAIN PAGE'!$B$12*A22) -> 0.04 | C22: =-'MAIN PAGE'!$B$13*(2*PI()*'MAIN PAGE'!$B$12)*SIN(2*PI()*'MAIN PAGE'!$B$12*'Wing Flap (particle)'!A22) -> -1.6164091e-15 | D22: =-'MAIN PAGE'!$B$13*(2*PI()*'MAIN PAGE'!$B$12)^2*COS(2*PI()*'MAIN PAGE'!$B$12*'Wing Flap (particle)'!A22) -> -157.91367 | E22: =D22*$I$10 -> -0.39478418 | F22: =E22*2 -> -0.78956835
A23: **for 10 hz shows one period of motion estimated using cos wave

Sheet Variable AOA Dihedral
A1: AOA (deg) | B1: Cross section | C1: Cd | D1: Drag | E1: Dz (down) | F1: Dx (back) | G1: Cl | H1: Lift | I1: Lz (up) | J1: Lx (back) | K1: Weight (down) | M1: NET X (back) | N1: NET Z (up) | O1: Lift Torque | P1: Gravity Torque | Q1: Net Torque
A3: 0 | B3: ='MAIN PAGE'!$B$17*SIN(RADIANS(A3))+'MAIN PAGE'!$G$3 -> 1.6e-05 | C3: 0.015 | D3: =(1/2)*'MAIN PAGE'!$B$2*'MAIN PAGE'!$B$5^2*B3*C3 -> 3.6123e-06 | E3: =D3*SIN(RADIANS(A3)) -> 0 | F3: =D3*COS(RADIANS(A3)) -> 3.6123e-06 | G3: 0 | H3: =(1/2)*'MAIN PAGE'!$B$2*'MAIN PAGE'!$B$5^2*'MAIN PAGE'!$G$6*G3*SIN(RADIANS(90-'MAIN PAGE'!$B$22)) -> 0 | I3: =H3*SIN(RADIANS(90-A3)) -> 0 | J3: =H3*COS(RADIANS(90-A3)) -> 0 | K3: ='MAIN PAGE'!$G$29 -> 0.0045415395 | M3: =-(F3+J3) -> -3.6123e-06 | N3: =I3-E3-K3 -> -0.0045415395
A4: 1 | B4: ='MAIN PAGE'!$B$17*SIN(RADIANS(A4))+'MAIN PAGE'!$G$3 -> 0.00053957219 | C4: 0.016 | D4: =(1/2)*'MAIN PAGE'!$B$2*'MAIN PAGE'!$B$5^2*B4*C4 -> 0.00012993978 | E4: =D4*SIN(RADIANS(A4)) -> 2.2677618e-06 | F4: =D4*COS(RADIANS(A4)) -> 0.00012991999 | G4: 0.1 | H4: =(1/2)*'MAIN PAGE'!$B$2*'MAIN PAGE'!$B$5^2*'MAIN PAGE'!$G$6*G4*SIN(RADIANS(90-'MAIN PAGE'!$B$22)) -> 0.0017787105 | I4: =H4*SIN(RADIANS(90-A4)) -> 0.0017784396 | J4: =H4*COS(RADIANS(90-A4)) -> 3.1042779e-05 | K4: ='MAIN PAGE'!$G$29 -> 0.0045415395 | M4: =-(F4+J4) -> -0.00016096276 | N4: =I4-E4-K4 -> -0.0027653676
A5: 2 | B5: ='MAIN PAGE'!$B$17*SIN(RADIANS(A5))+'MAIN PAGE'!$G$3 -> 0.0010629849 | C5: 0.017 | D5: =(1/2)*'MAIN PAGE'!$B$2*'MAIN PAGE'!$B$5^2*B5*C5 -> 0.00027198728 | E5: =D5*SIN(RADIANS(A5)) -> 9.492219e-06 | F5: =D5*COS(RADIANS(A5)) -> 0.00027182159 | G5: 0.2 | H5: =(1/2)*'MAIN PAGE'!$B$2*'MAIN PAGE'!$B$5^2*'MAIN PAGE'!$G$6*G5*SIN(RADIANS(90-'MAIN PAGE'!$B$22)) -> 0.003557421 | I5: =H5*SIN(RADIANS(90-A5)) -> 0.003555254 | J5: =H5*COS(RADIANS(90-A5)) -> 0.0001241522 | K5: ='MAIN PAGE'!$G$29 -> 0.0045415395 | M5: =-(F5+J5) -> -0.00039597379 | N5: =I5-E5-K5 -> -0.00099577776
A6: 3 | B6: ='MAIN PAGE'!$B$17*SIN(RADIANS(A6))+'MAIN PAGE'!$G$3 -> 0.0015860787 | C6: 0.019 | D6: =(1/2)*'MAIN PAGE'!$B$2*'MAIN PAGE'!$B$5^2*B6*C6 -> 0.00045357687 | E6: =D6*SIN(RADIANS(A6)) -> 2.3738379e-05 | F6: =D6*COS(RADIANS(A6)) -> 0.00045295526 | G6: 0.3 | H6: =(1/2)*'MAIN PAGE'!$B$2*'MAIN PAGE'!$B$5^2*'MAIN PAGE'!$G$6*G6*SIN(RADIANS(90-'MAIN PAGE'!$B$22)) -> 0.0053361316 | I6: =H6*SIN(RADIANS(90-A6)) -> 0.0053288186 | J6: =H6*COS(RADIANS(90-A6)) -> 0.00027927155 | K6: ='MAIN PAGE'!$G$29 -> 0.0045415395 | M6: =-(F6+J6) -> -0.00073222681 | N6: =I6-E6-K6 -> 0.00076354071
A7: 4 | B7: ='MAIN PAGE'!$B$17*SIN(RADIANS(A7))+'MAIN PAGE'!$G$3 -> 0.0021086942 | C7: 0.022 | D7: =(1/2)*'MAIN PAGE'!$B$2*'MAIN PAGE'!$B$5^2*B7*C7 -> 0.00069824664 | E7: =D7*SIN(RADIANS(A7)) -> 4.8707224e-05 | F7: =D7*COS(RADIANS(A7)) -> 0.00069654575 | G7: 0.4 | H7: =(1/2)*'MAIN PAGE'!$B$2*'MAIN PAGE'!$B$5^2*'MAIN PAGE'!$G$6*G7*SIN(RADIANS(90-'MAIN PAGE'!$B$22)) -> 0.0071148421 | I7: =H7*SIN(RADIANS(90-A7)) -> 0.0070975107 | J7: =H7*COS(RADIANS(90-A7)) -> 0.0004963063 | K7: ='MAIN PAGE'!$G$29 -> 0.0045415395 | M7: =-(F7+J7) -> -0.001192852 | N7: =I7-E7-K7 -> 0.002507264
A8: 5 | B8: ='MAIN PAGE'!$B$17*SIN(RADIANS(A8))+'MAIN PAGE'!$G$3 -> 0.0026306723 | C8: 0.03 | D8: =(1/2)*'MAIN PAGE'!$B$2*'MAIN PAGE'!$B$5^2*B8*C8 -> 0.0011878472 | E8: =D8*SIN(RADIANS(A8)) -> 0.0001035277 | F8: =D8*COS(RADIANS(A8)) -> 0.0011833271 | G8: 0.5 | H8: =(1/2)*'MAIN PAGE'!$B$2*'MAIN PAGE'!$B$5^2*'MAIN PAGE'!$G$6*G8*SIN(RADIANS(90-'MAIN PAGE'!$B$22)) -> 0.0088935526 | I8: =H8*SIN(RADIANS(90-A8)) -> 0.00885971 | J8: =H8*COS(RADIANS(90-A8)) -> 0.00077512418 | K8: ='MAIN PAGE'!$G$29 -> 0.0045415395 | M8: =-(F8+J8) -> -0.0019584513 | N8: =I8-E8-K8 -> 0.0042146428
A9: 6 | B9: ='MAIN PAGE'!$B$17*SIN(RADIANS(A9))+'MAIN PAGE'!$G$3 -> 0.0031518539 | C9: 0.04 | D9: =(1/2)*'MAIN PAGE'!$B$2*'MAIN PAGE'!$B$5^2*B9*C9 -> 0.0018975736 | E9: =D9*SIN(RADIANS(A9)) -> 0.00019835046 | F9: =D9*COS(RADIANS(A9)) -> 0.0018871785 | G9: 0.54 | H9: =(1/2)*'MAIN PAGE'!$B$2*'MAIN PAGE'!$B$5^2*'MAIN PAGE'!$G$6*G9*SIN(RADIANS(90-'MAIN PAGE'!$B$22)) -> 0.0096050368 | I9: =H9*SIN(RADIANS(90-A9)) -> 0.0095524194 | J9: =H9*COS(RADIANS(90-A9)) -> 0.0010039997 | K9: ='MAIN PAGE'!$G$29 -> 0.0045415395 | M9: =-(F9+J9) -> -0.0028911783 | N9: =I9-E9-K9 -> 0.0048125295
A10: 7 | B10: ='MAIN PAGE'!$B$17*SIN(RADIANS(A10))+'MAIN PAGE'!$G$3 -> 0.0036720803 | C10: 0.05 | D10: =(1/2)*'MAIN PAGE'!$B$2*'MAIN PAGE'!$B$5^2*B10*C10 -> 0.0027634699 | E10: =D10*SIN(RADIANS(A10)) -> 0.00033678227 | F10: =D10*COS(RADIANS(A10)) -> 0.0027428714 | G10: 0.58 | H10: =(1/2)*'MAIN PAGE'!$B$2*'MAIN PAGE'!$B$5^2*'MAIN PAGE'!$G$6*G10*SIN(RADIANS(90-'MAIN PAGE'!$B$22)) -> 0.010316521 | I10: =H10*SIN(RADIANS(90-A10)) -> 0.010239623 | J10: =H10*COS(RADIANS(90-A10)) -> 0.0012572676 | K10: ='MAIN PAGE'!$G$29 -> 0.0045415395 | M10: =-(F10+J10) -> -0.0040001391 | N10: =I10-E10-K10 -> 0.0053613015
A11: 8 | B11: ='MAIN PAGE'!$B$17*SIN(RADIANS(A11))+'MAIN PAGE'!$G$3 -> 0.004191193 | C11: 0.06 | D11: =(1/2)*'MAIN PAGE'!$B$2*'MAIN PAGE'!$B$5^2*B11*C11 -> 0.0037849616 | E11: =D11*SIN(RADIANS(A11)) -> 0.00052676485 | F11: =D11*COS(RADIANS(A11)) -> 0.0037481267 | G11: 0.62 | H11: =(1/2)*'MAIN PAGE'!$B$2*'MAIN PAGE'!$B$5^2*'MAIN PAGE'!$G$6*G11*SIN(RADIANS(90-'MAIN PAGE'!$B$22)) -> 0.011028005 | I11: =H11*SIN(RADIANS(90-A11)) -> 0.010920681 | J11: =H11*COS(RADIANS(90-A11)) -> 0.0015348017 | K11: ='MAIN PAGE'!$G$29 -> 0.0045415395 | M11: =-(F11+J11) -> -0.0052829283 | N11: =I11-E11-K11 -> 0.0058523771
A12: 9 | B12: ='MAIN PAGE'!$B$17*SIN(RADIANS(A12))+'MAIN PAGE'!$G$3 -> 0.004709034 | C12: 0.07 | D12: =(1/2)*'MAIN PAGE'!$B$2*'MAIN PAGE'!$B$5^2*B12*C12 -> 0.0049613793 | E12: =D12*SIN(RADIANS(A12)) -> 0.00077613072 | F12: =D12*COS(RADIANS(A12)) -> 0.0049002965 | G12: 0.66 | H12: =(1/2)*'MAIN PAGE'!$B$2*'MAIN PAGE'!$B$5^2*'MAIN PAGE'!$G$6*G12*SIN(RADIANS(90-'MAIN PAGE'!$B$22)) -> 0.011739489 | I12: =H12*SIN(RADIANS(90-A12)) -> 0.011594957 | J12: =H12*COS(RADIANS(90-A12)) -> 0.0018364608 | K12: ='MAIN PAGE'!$G$29 -> 0.0045415395 | M12: =-(F12+J12) -> -0.0067367572 | N12: =I12-E12-K12 -> 0.0062772866
A13: 10 | B13: ='MAIN PAGE'!$B$17*SIN(RADIANS(A13))+'MAIN PAGE'!$G$3 -> 0.0052254453 | C13: 0.08 | D13: =(1/2)*'MAIN PAGE'!$B$2*'MAIN PAGE'!$B$5^2*B13*C13 -> 0.0062919587 | E13: =D13*SIN(RADIANS(A13)) -> 0.0010925872 | F13: =D13*COS(RADIANS(A13)) -> 0.0061963697 | G13: 0.68 | H13: =(1/2)*'MAIN PAGE'!$B$2*'MAIN PAGE'!$B$5^2*'MAIN PAGE'!$G$6*G13*SIN(RADIANS(90-'MAIN PAGE'!$B$22)) -> 0.012095232 | I13: =H13*SIN(RADIANS(90-A13)) -> 0.011911478 | J13: =H13*COS(RADIANS(90-A13)) -> 0.0021003149 | K13: ='MAIN PAGE'!$G$29 -> 0.0045415395 | M13: =-(F13+J13) -> -0.0082966846 | N13: =I13-E13-K13 -> 0.0062773511
A14: 11 | B14: ='MAIN PAGE'!$B$17*SIN(RADIANS(A14))+'MAIN PAGE'!$G$3 -> 0.0057402699 | C14: 0.09 | D14: =(1/2)*'MAIN PAGE'!$B$2*'MAIN PAGE'!$B$5^2*B14*C14 -> 0.0077758413 | E14: =D14*SIN(RADIANS(A14)) -> 0.0014837005 | F14: =D14*COS(RADIANS(A14)) -> 0.0076329772 | G14: 0.7 | H14: =(1/2)*'MAIN PAGE'!$B$2*'MAIN PAGE'!$B$5^2*'MAIN PAGE'!$G$6*G14*SIN(RADIANS(90-'MAIN PAGE'!$B$22)) -> 0.012450974 | I14: =H14*SIN(RADIANS(90-A14)) -> 0.012222214 | J14: =H14*COS(RADIANS(90-A14)) -> 0.0023757578 | K14: ='MAIN PAGE'!$G$29 -> 0.0045415395 | M14: =-(F14+J14) -> -0.010008735 | N14: =I14-E14-K14 -> 0.0061969742
A15: 12 | B15: ='MAIN PAGE'!$B$17*SIN(RADIANS(A15))+'MAIN PAGE'!$G$3 -> 0.0062533507 | C15: 0.1 | D15: =(1/2)*'MAIN PAGE'!$B$2*'MAIN PAGE'!$B$5^2*B15*C15 -> 0.0094120745 | E15: =D15*SIN(RADIANS(A15)) -> 0.0019568803 | F15: =D15*COS(RADIANS(A15)) -> 0.0092063981 | G15: 0.68 | H15: =(1/2)*'MAIN PAGE'!$B$2*'MAIN PAGE'!$B$5^2*'MAIN PAGE'!$G$6*G15*SIN(RADIANS(90-'MAIN PAGE'!$B$22)) -> 0.012095232 | I15: =H15*SIN(RADIANS(90-A15)) -> 0.011830922 | J15: =H15*COS(RADIANS(90-A15)) -> 0.00251474 | K15: ='MAIN PAGE'!$G$29 -> 0.0045415395 | M15: =-(F15+J15) -> -0.011721138 | N15: =I15-E15-K15 -> 0.0053325019

Sheet Variable AOA Airfoil Frame
A1: AOA (deg) | B1: Cross section | C1: Cd | D1: Drag | E1: Dz (down) | F1: Dx (back) | G1: Cl | H1: Lift | I1: Lz (up) | J1: Lx (back) | K1: Weight (down) | M1: NET X (back) | N1: NET Z (up) | O1: Lift Torque | P1: Gravity Torque | Q1: Net Torque
A3: 0 | B3: ='MAIN PAGE'!$B$17*SIN(RADIANS(A3))+'MAIN PAGE'!$G$3 -> 1.6e-05 | C3: 0.01 | D3: =(1/2)*'MAIN PAGE'!$B$2*'MAIN PAGE'!$B$5^2*B3*C3 -> 2.4082e-06 | E3: =D3*SIN(RADIANS(A3)) -> 0 | F3: =D3*COS(RADIANS(A3)) -> 2.4082e-06 | G3: 0 | H3: =(1/2)*'MAIN PAGE'!$B$2*'MAIN PAGE'!$B$5^2*'MAIN PAGE'!$G$6*G3*SIN(RADIANS(90-'MAIN PAGE'!$B$22)) -> 0 | I3: =H3*SIN(RADIANS(90-A3)) -> 0 | J3: =H3*COS(RADIANS(90-A3)) -> 0 | K3: ='MAIN PAGE'!O52 -> 0.0045415395 | M3: =-(F3+J3) -> -2.4082e-06 | N3: =I3-E3-K3 -> -0.0045415395
A4: 1 | B4: ='MAIN PAGE'!$B$17*SIN(RADIANS(A4))+'MAIN PAGE'!$G$3 -> 0.00053957219 | C4: 0.012 | D4: =(1/2)*'MAIN PAGE'!$B$2*'MAIN PAGE'!$B$5^2*B4*C4 -> 9.7454832e-05 | E4: =D4*SIN(RADIANS(A4)) -> 1.7008213e-06 | F4: =D4*COS(RADIANS(A4)) -> 9.7439989e-05 | G4: 0.15 | H4: =(1/2)*'MAIN PAGE'!$B$2*'MAIN PAGE'!$B$5^2*'MAIN PAGE'!$G$6*G4*SIN(RADIANS(90-'MAIN PAGE'!$B$22)) -> 0.0026680658 | I4: =H4*SIN(RADIANS(90-A4)) -> 0.0026676594 | J4: =H4*COS(RADIANS(90-A4)) -> 4.6564168e-05 | K4: =K3 -> 0.0045415395 | M4: =-(F4+J4) -> -0.00014400416 | N4: =I4-E4-K4 -> -0.0018755809
A5: 2 | B5: ='MAIN PAGE'!$B$17*SIN(RADIANS(A5))+'MAIN PAGE'!$G$3 -> 0.0010629849 | C5: 0.014 | D5: =(1/2)*'MAIN PAGE'!$B$2*'MAIN PAGE'!$B$5^2*B5*C5 -> 0.00022398952 | E5: =D5*SIN(RADIANS(A5)) -> 7.8171215e-06 | F5: =D5*COS(RADIANS(A5)) -> 0.00022385307 | G5: 0.3 | H5: =(1/2)*'MAIN PAGE'!$B$2*'MAIN PAGE'!$B$5^2*'MAIN PAGE'!$G$6*G5*SIN(RADIANS(90-'MAIN PAGE'!$B$22)) -> 0.0053361316 | I5: =H5*SIN(RADIANS(90-A5)) -> 0.0053328809 | J5: =H5*COS(RADIANS(90-A5)) -> 0.00018622831 | K5: =K3 -> 0.0045415395 | M5: =-(F5+J5) -> -0.00041008138 | N5: =I5-E5-K5 -> 0.00078352432
A6: 3 | B6: ='MAIN PAGE'!$B$17*SIN(RADIANS(A6))+'MAIN PAGE'!$G$3 -> 0.0015860787 | C6: 0.016 | D6: =(1/2)*'MAIN PAGE'!$B$2*'MAIN PAGE'!$B$5^2*B6*C6 -> 0.00038195947 | E6: =D6*SIN(RADIANS(A6)) -> 1.9990214e-05 | F6: =D6*COS(RADIANS(A6)) -> 0.00038143601 | G6: 0.45 | H6: =(1/2)*'MAIN PAGE'!$B$2*'MAIN PAGE'!$B$5^2*'MAIN PAGE'!$G$6*G6*SIN(RADIANS(90-'MAIN PAGE'!$B$22)) -> 0.0080041974 | I6: =H6*SIN(RADIANS(90-A6)) -> 0.0079932279 | J6: =H6*COS(RADIANS(90-A6)) -> 0.00041890732 | K6: =K3 -> 0.0045415395 | M6: =-(F6+J6) -> -0.00080034333 | N6: =I6-E6-K6 -> 0.0034316982
A7: 4 | B7: ='MAIN PAGE'!$B$17*SIN(RADIANS(A7))+'MAIN PAGE'!$G$3 -> 0.0021086942 | C7: 0.018 | D7: =(1/2)*'MAIN PAGE'!$B$2*'MAIN PAGE'!$B$5^2*B7*C7 -> 0.00057129271 | E7: =D7*SIN(RADIANS(A7)) -> 3.9851365e-05 | F7: =D7*COS(RADIANS(A7)) -> 0.00056990107 | G7: 0.6 | H7: =(1/2)*'MAIN PAGE'!$B$2*'MAIN PAGE'!$B$5^2*'MAIN PAGE'!$G$6*G7*SIN(RADIANS(90-'MAIN PAGE'!$B$22)) -> 0.010672263 | I7: =H7*SIN(RADIANS(90-A7)) -> 0.010646266 | J7: =H7*COS(RADIANS(90-A7)) -> 0.00074445944 | K7: =K3 -> 0.0045415395 | M7: =-(F7+J7) -> -0.0013143605 | N7: =I7-E7-K7 -> 0.0060648752
A8: 5 | B8: ='MAIN PAGE'!$B$17*SIN(RADIANS(A8))+'MAIN PAGE'!$G$3 -> 0.0026306723 | C8: 0.02 | D8: =(1/2)*'MAIN PAGE'!$B$2*'MAIN PAGE'!$B$5^2*B8*C8 -> 0.00079189812 | E8: =D8*SIN(RADIANS(A8)) -> 6.9018469e-05 | F8: =D8*COS(RADIANS(A8)) -> 0.00078888471 | G8: 0.8 | H8: =(1/2)*'MAIN PAGE'!$B$2*'MAIN PAGE'!$B$5^2*'MAIN PAGE'!$G$6*G8*SIN(RADIANS(90-'MAIN PAGE'!$B$22)) -> 0.014229684 | I8: =H8*SIN(RADIANS(90-A8)) -> 0.014175536 | J8: =H8*COS(RADIANS(90-A8)) -> 0.0012401987 | K8: =K3 -> 0.0045415395 | M8: =-(F8+J8) -> -0.0020290834 | N8: =I8-E8-K8 -> 0.009564978
A9: 6 | B9: ='MAIN PAGE'!$B$17*SIN(RADIANS(A9))+'MAIN PAGE'!$G$3 -> 0.0031518539 | C9: 0.022 | D9: =(1/2)*'MAIN PAGE'!$B$2*'MAIN PAGE'!$B$5^2*B9*C9 -> 0.0010436655 | E9: =D9*SIN(RADIANS(A9)) -> 0.00010909275 | F9: =D9*COS(RADIANS(A9)) -> 0.0010379482 | G9: 0.9 | H9: =(1/2)*'MAIN PAGE'!$B$2*'MAIN PAGE'!$B$5^2*'MAIN PAGE'!$G$6*G9*SIN(RADIANS(90-'MAIN PAGE'!$B$22)) -> 0.016008395 | I9: =H9*SIN(RADIANS(90-A9)) -> 0.015920699 | J9: =H9*COS(RADIANS(90-A9)) -> 0.0016733329 | K9: =K3 -> 0.0045415395 | M9: =-(F9+J9) -> -0.0027112811 | N9: =I9-E9-K9 -> 0.011270067
A10: 7 | B10: ='MAIN PAGE'!$B$17*SIN(RADIANS(A10))+'MAIN PAGE'!$G$3 -> 0.0036720803 | C10: 0.024 | D10: =(1/2)*'MAIN PAGE'!$B$2*'MAIN PAGE'!$B$5^2*B10*C10 -> 0.0013264656 | E10: =D10*SIN(RADIANS(A10)) -> 0.00016165549 | F10: =D10*COS(RADIANS(A10)) -> 0.0013165783 | G10: 1 | H10: =(1/2)*'MAIN PAGE'!$B$2*'MAIN PAGE'!$B$5^2*'MAIN PAGE'!$G$6*G10*SIN(RADIANS(90-'MAIN PAGE'!$B$22)) -> 0.017787105 | I10: =H10*SIN(RADIANS(90-A10)) -> 0.017654523 | J10: =H10*COS(RADIANS(90-A10)) -> 0.0021677028 | K10: =K3 -> 0.0045415395 | M10: =-(F10+J10) -> -0.0034842811 | N10: =I10-E10-K10 -> 0.012951328
A11: 8 | B11: ='MAIN PAGE'!$B$17*SIN(RADIANS(A11))+'MAIN PAGE'!$G$3 -> 0.004191193 | C11: 0.026 | D11: =(1/2)*'MAIN PAGE'!$B$2*'MAIN PAGE'!$B$5^2*B11*C11 -> 0.00164015 | E11: =D11*SIN(RADIANS(A11)) -> 0.00022826477 | F11: =D11*COS(RADIANS(A11)) -> 0.0016241882 | G11: 1.1 | H11: =(1/2)*'MAIN PAGE'!$B$2*'MAIN PAGE'!$B$5^2*'MAIN PAGE'!$G$6*G11*SIN(RADIANS(90-'MAIN PAGE'!$B$22)) -> 0.019565816 | I11: =H11*SIN(RADIANS(90-A11)) -> 0.019375403 | J11: =H11*COS(RADIANS(90-A11)) -> 0.0027230353 | K11: =K3 -> 0.0045415395 | M11: =-(F11+J11) -> -0.0043472235 | N11: =I11-E11-K11 -> 0.014605598
A12: 9 | B12: ='MAIN PAGE'!$B$17*SIN(RADIANS(A12))+'MAIN PAGE'!$G$3 -> 0.004709034 | C12: 0.028 | D12: =(1/2)*'MAIN PAGE'!$B$2*'MAIN PAGE'!$B$5^2*B12*C12 -> 0.0019845517 | E12: =D12*SIN(RADIANS(A12)) -> 0.00031045229 | F12: =D12*COS(RADIANS(A12)) -> 0.0019601186 | G12: 1.2 | H12: =(1/2)*'MAIN PAGE'!$B$2*'MAIN PAGE'!$B$5^2*'MAIN PAGE'!$G$6*G12*SIN(RADIANS(90-'MAIN PAGE'!$B$22)) -> 0.021344526 | I12: =H12*SIN(RADIANS(90-A12)) -> 0.02108174 | J12: =H12*COS(RADIANS(90-A12)) -> 0.0033390195 | K12: =K3 -> 0.0045415395 | M12: =-(F12+J12) -> -0.0052991381 | N12: =I12-E12-K12 -> 0.016229748
A13: 10 | B13: ='MAIN PAGE'!$B$17*SIN(RADIANS(A13))+'MAIN PAGE'!$G$3 -> 0.0052254453 | C13: 0.03 | D13: =(1/2)*'MAIN PAGE'!$B$2*'MAIN PAGE'!$B$5^2*B13*C13 -> 0.0023594845 | E13: =D13*SIN(RADIANS(A13)) -> 0.00040972019 | F13: =D13*COS(RADIANS(A13)) -> 0.0023236386 | G13: 1.3 | H13: =(1/2)*'MAIN PAGE'!$B$2*'MAIN PAGE'!$B$5^2*'MAIN PAGE'!$G$6*G13*SIN(RADIANS(90-'MAIN PAGE'!$B$22)) -> 0.023123237 | I13: =H13*SIN(RADIANS(90-A13)) -> 0.022771943 | J13: =H13*COS(RADIANS(90-A13)) -> 0.0040153079 | K13: =K3 -> 0.0045415395 | M13: =-(F13+J13) -> -0.0063389466 | N13: =I13-E13-K13 -> 0.017820683
A14: 11 | B14: ='MAIN PAGE'!$B$17*SIN(RADIANS(A14))+'MAIN PAGE'!$G$3 -> 0.0057402699 | C14: 0.05 | D14: =(1/2)*'MAIN PAGE'!$B$2*'MAIN PAGE'!$B$5^2*B14*C14 -> 0.0043199118 | E14: =D14*SIN(RADIANS(A14)) -> 0.00082427804 | F14: =D14*COS(RADIANS(A14)) -> 0.0042405429 | G14: 1.3 | H14: =(1/2)*'MAIN PAGE'!$B$2*'MAIN PAGE'!$B$5^2*'MAIN PAGE'!$G$6*G14*SIN(RADIANS(90-'MAIN PAGE'!$B$22)) -> 0.023123237 | I14: =H14*SIN(RADIANS(90-A14)) -> 0.022698398 | J14: =H14*COS(RADIANS(90-A14)) -> 0.0044121216 | K14: =K3 -> 0.0045415395 | M14: =-(F14+J14) -> -0.0086526645 | N14: =I14-E14-K14 -> 0.01733258
A15: 12 | B15: ='MAIN PAGE'!$B$17*SIN(RADIANS(A15))+'MAIN PAGE'!$G$3 -> 0.0062533507 | C15: 0.06 | D15: =(1/2)*'MAIN PAGE'!$B$2*'MAIN PAGE'!$B$5^2*B15*C15 -> 0.0056472447 | E15: =D15*SIN(RADIANS(A15)) -> 0.0011741282 | F15: =D15*COS(RADIANS(A15)) -> 0.0055238389 | G15: 1.3 | H15: =(1/2)*'MAIN PAGE'!$B$2*'MAIN PAGE'!$B$5^2*'MAIN PAGE'!$G$6*G15*SIN(RADIANS(90-'MAIN PAGE'!$B$22)) -> 0.023123237 | I15: =H15*SIN(RADIANS(90-A15)) -> 0.022617939 | J15: =H15*COS(RADIANS(90-A15)) -> 0.0048075913 | K15: =K3 -> 0.0045415395 | M15: =-(F15+J15) -> -0.01033143 | N15: =I15-E15-K15 -> 0.016902271
J32: **These r from S7055

Sheet ignore
A1: Flapping Data | B1: position (θ) | C1: velocity (ω) | D1: acceleration (α) | E1: torque (τ) | G1: Wing Calculations
A2: sec | B2: rad | C2: rad/s | D2: rad/s^2 | E2: Nm | G2: **estimate as rectangle
A3: 0 | B3: ='MAIN PAGE'!$B$13*COS(2*PI()*'MAIN PAGE'!$B$12*A3) -> 0.04 | C3: =-'MAIN PAGE'!$B$13*(2*PI()*'MAIN PAGE'!$B$12)*SIN(2*PI()*'MAIN PAGE'!$B$12*ignore!A3) -> 0 | D3: =-'MAIN PAGE'!$B$13*((2*PI()*'MAIN PAGE'!$B$12)^2)*COS(2*PI()*'MAIN PAGE'!$B$12*ignore!A3) -> -157.91367 | E3: =D3*$H$13 -> -0.0069745204
A4: 0.01 | B4: ='MAIN PAGE'!$B$13*COS(2*PI()*'MAIN PAGE'!$B$12*A4) -> 0.03236068 | C4: =-'MAIN PAGE'!$B$13*(2*PI()*'MAIN PAGE'!$B$12)*SIN(2*PI()*'MAIN PAGE'!$B$12*ignore!A4) -> -1.4772655 | D4: =-'MAIN PAGE'!$B$13*(2*PI()*'MAIN PAGE'!$B$12)^2*COS(2*PI()*'MAIN PAGE'!$B$12*ignore!A4) -> -127.75484 | E4: =D4*$H$13 -> -0.0056425056 | G4: chord | H4: 0.06 | I4: m
A5: =A4+0.005 -> 0.015 | B5: ='MAIN PAGE'!$B$13*COS(2*PI()*'MAIN PAGE'!$B$12*A5) -> 0.02351141 | C5: =-'MAIN PAGE'!$B$13*(2*PI()*'MAIN PAGE'!$B$12)*SIN(2*PI()*'MAIN PAGE'!$B$12*ignore!A5) -> -2.0332815 | D5: =-'MAIN PAGE'!$B$13*(2*PI()*'MAIN PAGE'!$B$12)^2*COS(2*PI()*'MAIN PAGE'!$B$12*ignore!A5) -> -92.819327 | E5: =D5*$H$13 -> -0.0040995203 | G5: span | H5: 0.16 | I5: m
A6: =A5+0.005 -> 0.02 | B6: ='MAIN PAGE'!$B$13*COS(2*PI()*'MAIN PAGE'!$B$12*A6) -> 0.01236068 | C6: =-'MAIN PAGE'!$B$13*(2*PI()*'MAIN PAGE'!$B$12)*SIN(2*PI()*'MAIN PAGE'!$B$12*ignore!A6) -> -2.3902657 | D6: =-'MAIN PAGE'!$B$13*(2*PI()*'MAIN PAGE'!$B$12)^2*COS(2*PI()*'MAIN PAGE'!$B$12*ignore!A6) -> -48.798008 | E6: =D6*$H$13 -> -0.0021552453 | G6: area wing | H6: =H5*H4 -> 0.0096 | I6: m
A7: =A6+0.005 -> 0.025 | B7: ='MAIN PAGE'!$B$13*COS(2*PI()*'MAIN PAGE'!$B$12*A7) -> 2.4502969e-18 | C7: =-'MAIN PAGE'!$B$13*(2*PI()*'MAIN PAGE'!$B$12)*SIN(2*PI()*'MAIN PAGE'!$B$12*ignore!A7) -> -2.5132741 | D7: =-'MAIN PAGE'!$B$13*(2*PI()*'MAIN PAGE'!$B$12)^2*COS(2*PI()*'MAIN PAGE'!$B$12*ignore!A7) -> -9.6733845e-15 | E7: =D7*$H$13 -> -4.2724115e-19 | G7: thickness | H7: 0.001 | I7: m
A8: =A7+0.005 -> 0.03 | B8: ='MAIN PAGE'!$B$13*COS(2*PI()*'MAIN PAGE'!$B$12*A8) -> -0.01236068 | C8: =-'MAIN PAGE'!$B$13*(2*PI()*'MAIN PAGE'!$B$12)*SIN(2*PI()*'MAIN PAGE'!$B$12*ignore!A8) -> -2.3902657 | D8: =-'MAIN PAGE'!$B$13*(2*PI()*'MAIN PAGE'!$B$12)^2*COS(2*PI()*'MAIN PAGE'!$B$12*ignore!A8) -> 48.798008 | E8: =D8*$H$13 -> 0.0021552453 | G8: volume | H8: =H6*H7 -> 9.6e-06 | I8: m^2
A9: =A8+0.005 -> 0.035 | B9: ='MAIN PAGE'!$B$13*COS(2*PI()*'MAIN PAGE'!$B$12*A9) -> -0.02351141 | C9: =-'MAIN PAGE'!$B$13*(2*PI()*'MAIN PAGE'!$B$12)*SIN(2*PI()*'MAIN PAGE'!$B$12*ignore!A9) -> -2.0332815 | D9: =-'MAIN PAGE'!$B$13*(2*PI()*'MAIN PAGE'!$B$12)^2*COS(2*PI()*'MAIN PAGE'!$B$12*ignore!A9) -> 92.819327 | E9: =D9*$H$13 -> 0.0040995203 | G9: density material
A10: =A9+0.005 -> 0.04 | B10: ='MAIN PAGE'!$B$13*COS(2*PI()*'MAIN PAGE'!$B$12*A10) -> -0.03236068 | C10: =-'MAIN PAGE'!$B$13*(2*PI()*'MAIN PAGE'!$B$12)*SIN(2*PI()*'MAIN PAGE'!$B$12*ignore!A10) -> -1.4772655 | D10: =-'MAIN PAGE'!$B$13*(2*PI()*'MAIN PAGE'!$B$12)^2*COS(2*PI()*'MAIN PAGE'!$B$12*ignore!A10) -> 127.75484 | E10: =D10*$H$13 -> 0.0056425056 | G10: mass | H10: 0.005 | I10: kg
A11: =A10+0.005 -> 0.045 | B11: ='MAIN PAGE'!$B$13*COS(2*PI()*'MAIN PAGE'!$B$12*A11) -> -0.038042261 | C11: =-'MAIN PAGE'!$B$13*(2*PI()*'MAIN PAGE'!$B$12)*SIN(2*PI()*'MAIN PAGE'!$B$12*ignore!A11) -> -0.77664442 | D11: =-'MAIN PAGE'!$B$13*(2*PI()*'MAIN PAGE'!$B$12)^2*COS(2*PI()*'MAIN PAGE'!$B$12*ignore!A11) -> 150.18483 | E11: =D11*$H$13 -> 0.0066331631
A12: =A11+0.005 -> 0.05 | B12: ='MAIN PAGE'!$B$13*COS(2*PI()*'MAIN PAGE'!$B$12*A12) -> -0.04 | C12: =-'MAIN PAGE'!$B$13*(2*PI()*'MAIN PAGE'!$B$12)*SIN(2*PI()*'MAIN PAGE'!$B$12*ignore!A12) -> -1.4240313e-15 | D12: =-'MAIN PAGE'!$B$13*(2*PI()*'MAIN PAGE'!$B$12)^2*COS(2*PI()*'MAIN PAGE'!$B$12*ignore!A12) -> 157.91367 | E12: =D12*$H$13 -> 0.0069745204 | G12: Inertia center | H12: =(1/12)*H10*(H4^2+H5^2) -> 1.2166667e-05
A13: =A12+0.005 -> 0.055 | B13: ='MAIN PAGE'!$B$13*COS(2*PI()*'MAIN PAGE'!$B$12*A13) -> -0.038042261 | C13: =-'MAIN PAGE'!$B$13*(2*PI()*'MAIN PAGE'!$B$12)*SIN(2*PI()*'MAIN PAGE'!$B$12*ignore!A13) -> 0.77664442 | D13: =-'MAIN PAGE'!$B$13*(2*PI()*'MAIN PAGE'!$B$12)^2*COS(2*PI()*'MAIN PAGE'!$B$12*ignore!A13) -> 150.18483 | E13: =D13*$H$13 -> 0.0066331631 | G13: Inertia edge | H13: =H12+(H10*((1/2)*H5)^2) -> 4.4166667e-05 | I13: kg.m^2 | J13: check?? | K13: =(1/3)*H10*H5^2 -> 4.2666667e-05
A14: =A13+0.005 -> 0.06 | B14: ='MAIN PAGE'!$B$13*COS(2*PI()*'MAIN PAGE'!$B$12*A14) -> -0.03236068 | C14: =-'MAIN PAGE'!$B$13*(2*PI()*'MAIN PAGE'!$B$12)*SIN(2*PI()*'MAIN PAGE'!$B$12*ignore!A14) -> 1.4772655 | D14: =-'MAIN PAGE'!$B$13*(2*PI()*'MAIN PAGE'!$B$12)^2*COS(2*PI()*'MAIN PAGE'!$B$12*ignore!A14) -> 127.75484 | E14: =D14*$H$13 -> 0.0056425056
A15: =A14+0.005 -> 0.065 | B15: ='MAIN PAGE'!$B$13*COS(2*PI()*'MAIN PAGE'!$B$12*A15) -> -0.02351141 | C15: =-'MAIN PAGE'!$B$13*(2*PI()*'MAIN PAGE'!$B$12)*SIN(2*PI()*'MAIN PAGE'!$B$12*ignore!A15) -> 2.0332815 | D15: =-'MAIN PAGE'!$B$13*(2*PI()*'MAIN PAGE'!$B$12)^2*COS(2*PI()*'MAIN PAGE'!$B$12*ignore!A15) -> 92.819327 | E15: =D15*$H$13 -> 0.0040995203
A16: =A15+0.005 -> 0.07 | B16: ='MAIN PAGE'!$B$13*COS(2*PI()*'MAIN PAGE'!$B$12*A16) -> -0.01236068 | C16: =-'MAIN PAGE'!$B$13*(2*PI()*'MAIN PAGE'!$B$12)*SIN(2*PI()*'MAIN PAGE'!$B$12*ignore!A16) -> 2.3902657 | D16: =-'MAIN PAGE'!$B$13*(2*PI()*'MAIN PAGE'!$B$12)^2*COS(2*PI()*'MAIN PAGE'!$B$12*ignore!A16) -> 48.798008 | E16: =D16*$H$13 -> 0.0021552453
A17: =A16+0.005 -> 0.075 | B17: ='MAIN PAGE'!$B$13*COS(2*PI()*'MAIN PAGE'!$B$12*A17) -> -7.3508907e-18 | C17: =-'MAIN PAGE'!$B$13*(2*PI()*'MAIN PAGE'!$B$12)*SIN(2*PI()*'MAIN PAGE'!$B$12*ignore!A17) -> 2.5132741 | D17: =-'MAIN PAGE'!$B$13*(2*PI()*'MAIN PAGE'!$B$12)^2*COS(2*PI()*'MAIN PAGE'!$B$12*ignore!A17) -> 2.9020153e-14 | E17: =D17*$H$13 -> 1.2817234e-18
A18: =A17+0.005 -> 0.08 | B18: ='MAIN PAGE'!$B$13*COS(2*PI()*'MAIN PAGE'!$B$12*A18) -> 0.01236068 | C18: =-'MAIN PAGE'!$B$13*(2*PI()*'MAIN PAGE'!$B$12)*SIN(2*PI()*'MAIN PAGE'!$B$12*ignore!A18) -> 2.3902657 | D18: =-'MAIN PAGE'!$B$13*(2*PI()*'MAIN PAGE'!$B$12)^2*COS(2*PI()*'MAIN PAGE'!$B$12*ignore!A18) -> -48.798008 | E18: =D18*$H$13 -> -0.0021552453
A19: =A18+0.005 -> 0.085 | B19: ='MAIN PAGE'!$B$13*COS(2*PI()*'MAIN PAGE'!$B$12*A19) -> 0.02351141 | C19: =-'MAIN PAGE'!$B$13*(2*PI()*'MAIN PAGE'!$B$12)*SIN(2*PI()*'MAIN PAGE'!$B$12*ignore!A19) -> 2.0332815 | D19: =-'MAIN PAGE'!$B$13*(2*PI()*'MAIN PAGE'!$B$12)^2*COS(2*PI()*'MAIN PAGE'!$B$12*ignore!A19) -> -92.819327 | E19: =D19*$H$13 -> -0.0040995203
A20: =A19+0.005 -> 0.09 | B20: ='MAIN PAGE'!$B$13*COS(2*PI()*'MAIN PAGE'!$B$12*A20) -> 0.03236068 | C20: =-'MAIN PAGE'!$B$13*(2*PI()*'MAIN PAGE'!$B$12)*SIN(2*PI()*'MAIN PAGE'!$B$12*ignore!A20) -> 1.4772655 | D20: =-'MAIN PAGE'!$B$13*(2*PI()*'MAIN PAGE'!$B$12)^2*COS(2*PI()*'MAIN PAGE'!$B$12*ignore!A20) -> -127.75484 | E20: =D20*$H$13 -> -0.0056425056
A21: =A20+0.005 -> 0.095 | B21: ='MAIN PAGE'!$B$13*COS(2*PI()*'MAIN PAGE'!$B$12*A21) -> 0.038042261 | C21: =-'MAIN PAGE'!$B$13*(2*PI()*'MAIN PAGE'!$B$12)*SIN(2*PI()*'MAIN PAGE'!$B$12*ignore!A21) -> 0.77664442 | D21: =-'MAIN PAGE'!$B$13*(2*PI()*'MAIN PAGE'!$B$12)^2*COS(2*PI()*'MAIN PAGE'!$B$12*ignore!A21) -> -150.18483 | E21: =D21*$H$13 -> -0.0066331631
A22: =A21+0.005 -> 0.1 | B22: ='MAIN PAGE'!$B$13*COS(2*PI()*'MAIN PAGE'!$B$12*A22) -> 0.04 | C22: =-'MAIN PAGE'!$B$13*(2*PI()*'MAIN PAGE'!$B$12)*SIN(2*PI()*'MAIN PAGE'!$B$12*ignore!A22) -> -1.6164091e-15 | D22: =-'MAIN PAGE'!$B$13*(2*PI()*'MAIN PAGE'!$B$12)^2*COS(2*PI()*'MAIN PAGE'!$B$12*ignore!A22) -> -157.91367 | E22: =D22*$H$13 -> -0.0069745204
A23: **for 10 hz shows one period
